Workbook
Name cur_month: Dashboard!$F$6
Name cur_year: Dashboard!$F$5

Sheet Dashboard
E5: Year | F5: 2017
E6: Month | F6: Jun
E7: Division
F10: Revenue | N10: Profit | V10: Cash
F11: Actual | H11: % ∆ PY | K11: % ∆ B | N11: Actual | P11: % ∆ PY | S11: % ∆ B | V11: Actual | X11: % ∆ PY | AA11: % ∆ B
D13: =INDEX(Calculation!M15:M$34,Calculation!$D$5) -> 1 | E13: =INDEX(Calculation!N15:N$34,Calculation!$D$5) -> Commuta | F13: =INDEX(Calculation!O15:O$34,Calculation!$D$5) -> 6353 | H13: =INDEX(Calculation!X15:X$34,Calculation!$D$5) -> 0.060070082 | I13: =H13 -> 0.060070082 | K13: =INDEX(Calculation!AA15:AA$34,Calculation!$D$5) -> 0.20436019 | L13: =IF(K13="","",IF(K13>=0.05,"▲",IF(K13<-0.05,"▼",""))) -> ▲ | N13: =INDEX(Calculation!P15:P$34,Calculation!$D$5) -> 762 | P13: =INDEX(Calculation!Y15:Y$34,Calculation!$D$5) -> 0.1305638 | Q13: =P13 -> 0.1305638 | S13: =INDEX(Calculation!AB15:AB$34,Calculation!$D$5) -> 0.3415493 | T13: =IF(S13="","",IF(S13>=0.05,"▲",IF(S13<-0.05,"▼",""))) -> ▲ | V13: =INDEX(Calculation!Q15:Q$34,Calculation!$D$5) -> 7332 | X13: =INDEX(Calculation!Z15:Z$34,Calculation!$D$5) -> 0.023022185 | Y13: =X13 -> 0.023022185 | AA13: =INDEX(Calculation!AC15:AC$34,Calculation!$D$5) -> 0.01452885 | AB13: =IF(AA13="","",IF(AA13>=0.05,"▲",IF(AA13<-0.05,"▼","")))
D14: =INDEX(Calculation!M16:M$34,Calculation!$D$5) -> 2 | E14: =INDEX(Calculation!N16:N$34,Calculation!$D$5) -> Infic | F14: =INDEX(Calculation!O16:O$34,Calculation!$D$5) -> 12373 | H14: =INDEX(Calculation!X16:X$34,Calculation!$D$5) -> -0.0020164543 | I14: =H14 -> -0.0020164543 | K14: =INDEX(Calculation!AA16:AA$34,Calculation!$D$5) -> 0.1815317 | L14: =IF(K14="","",IF(K14>=0.05,"▲",IF(K14<-0.05,"▼",""))) -> ▲ | N14: =INDEX(Calculation!P16:P$34,Calculation!$D$5) -> 408 | P14: =INDEX(Calculation!Y16:Y$34,Calculation!$D$5) -> 0.19648094 | Q14: =P14 -> 0.19648094 | S14: =INDEX(Calculation!AB16:AB$34,Calculation!$D$5) -> -0.11496746 | T14: =IF(S14="","",IF(S14>=0.05,"▲",IF(S14<-0.05,"▼",""))) -> ▼ | V14: =INDEX(Calculation!Q16:Q$34,Calculation!$D$5) -> 3054 | X14: =INDEX(Calculation!Z16:Z$34,Calculation!$D$5) -> 0.0069238378 | Y14: =X14 -> 0.0069238378 | AA14: =INDEX(Calculation!AC16:AC$34,Calculation!$D$5) -> 0.049484536 | AB14: =IF(AA14="","",IF(AA14>=0.05,"▲",IF(AA14<-0.05,"▼","")))
D15: =INDEX(Calculation!M17:M$34,Calculation!$D$5) -> 3 | E15: =INDEX(Calculation!N17:N$34,Calculation!$D$5) -> Accord | F15: =INDEX(Calculation!O17:O$34,Calculation!$D$5) -> 17760 | H15: =INDEX(Calculation!X17:X$34,Calculation!$D$5) -> 0.043171806 | I15: =H15 -> 0.043171806 | K15: =INDEX(Calculation!AA17:AA$34,Calculation!$D$5) -> 0.053755785 | L15: =IF(K15="","",IF(K15>=0.05,"▲",IF(K15<-0.05,"▼",""))) -> ▲ | N15: =INDEX(Calculation!P17:P$34,Calculation!$D$5) -> 800 | P15: =INDEX(Calculation!Y17:Y$34,Calculation!$D$5) -> 0.4084507 | Q15: =P15 -> 0.4084507 | S15: =INDEX(Calculation!AB17:AB$34,Calculation!$D$5) -> 0.3986014 | T15: =IF(S15="","",IF(S15>=0.05,"▲",IF(S15<-0.05,"▼",""))) -> ▲ | V15: =INDEX(Calculation!Q17:Q$34,Calculation!$D$5) -> 6488 | X15: =INDEX(Calculation!Z17:Z$34,Calculation!$D$5) -> -0.13134288 | Y15: =X15 -> -0.13134288 | AA15: =INDEX(Calculation!AC17:AC$34,Calculation!$D$5) -> -0.018605355 | AB15: =IF(AA15="","",IF(AA15>=0.05,"▲",IF(AA15<-0.05,"▼","")))
D16: =INDEX(Calculation!M18:M$34,Calculation!$D$5) -> 4 | E16: =INDEX(Calculation!N18:N$34,Calculation!$D$5) -> Misty Wash | F16: =INDEX(Calculation!O18:O$34,Calculation!$D$5) -> 30399.6 | H16: =INDEX(Calculation!X18:X$34,Calculation!$D$5) -> 0.029392244 | I16: =H16 -> 0.029392244 | K16: =INDEX(Calculation!AA18:AA$34,Calculation!$D$5) -> 0.0053708677 | L16: =IF(K16="","",IF(K16>=0.05,"▲",IF(K16<-0.05,"▼",""))) | N16: =INDEX(Calculation!P18:P$34,Calculation!$D$5) -> 786.8 | P16: =INDEX(Calculation!Y18:Y$34,Calculation!$D$5) -> 0 | Q16: =P16 -> 0 | S16: =INDEX(Calculation!AB18:AB$34,Calculation!$D$5) -> -0.15615616 | T16: =IF(S16="","",IF(S16>=0.05,"▲",IF(S16<-0.05,"▼",""))) -> ▼ | V16: =INDEX(Calculation!Q18:Q$34,Calculation!$D$5) -> 12308.8 | X16: =INDEX(Calculation!Z18:Z$34,Calculation!$D$5) -> -0.11709179 | Y16: =X16 -> -0.11709179 | AA16: =INDEX(Calculation!AC18:AC$34,Calculation!$D$5) -> -0.080142289 | AB16: =IF(AA16="","",IF(AA16>=0.05,"▲",IF(AA16<-0.05,"▼",""))) -> ▼
D17: =INDEX(Calculation!M19:M$34,Calculation!$D$5) -> 5 | E17: =INDEX(Calculation!N19:N$34,Calculation!$D$5) -> Twenty20 | F17: =INDEX(Calculation!O19:O$34,Calculation!$D$5) -> 20400 | H17: =INDEX(Calculation!X19:X$34,Calculation!$D$5) -> -0.082073434 | I17: =H17 -> -0.082073434 | K17: =INDEX(Calculation!AA19:AA$34,Calculation!$D$5) -> 0.10408729 | L17: =IF(K17="","",IF(K17>=0.05,"▲",IF(K17<-0.05,"▼",""))) -> ▲ | N17: =INDEX(Calculation!P19:P$34,Calculation!$D$5) -> 614.4 | P17: =INDEX(Calculation!Y19:Y$34,Calculation!$D$5) -> -0.37864078 | Q17: =P17 -> -0.37864078 | S17: =INDEX(Calculation!AB19:AB$34,Calculation!$D$5) -> -0.45142857 | T17: =IF(S17="","",IF(S17>=0.05,"▲",IF(S17<-0.05,"▼",""))) -> ▼ | V17: =INDEX(Calculation!Q19:Q$34,Calculation!$D$5) -> 15171.2 | X17: =INDEX(Calculation!Z19:Z$34,Calculation!$D$5) -> -0.052936476 | Y17: =X17 -> -0.052936476 | AA17: =INDEX(Calculation!AC19:AC$34,Calculation!$D$5) -> 0.066111986 | AB17: =IF(AA17="","",IF(AA17>=0.05,"▲",IF(AA17<-0.05,"▼",""))) -> ▲
D18: =INDEX(Calculation!M20:M$34,Calculation!$D$5) -> 6 | E18: =INDEX(Calculation!N20:N$34,Calculation!$D$5) -> Tanox | F18: =INDEX(Calculation!O20:O$34,Calculation!$D$5) -> 21088 | H18: =INDEX(Calculation!X20:X$34,Calculation!$D$5) -> 0.068504256 | I18: =H18 -> 0.068504256 | K18: =INDEX(Calculation!AA20:AA$34,Calculation!$D$5) -> 0.10085613 | L18: =IF(K18="","",IF(K18>=0.05,"▲",IF(K18<-0.05,"▼",""))) -> ▲ | N18: =INDEX(Calculation!P20:P$34,Calculation!$D$5) -> 1264 | P18: =INDEX(Calculation!Y20:Y$34,Calculation!$D$5) -> 0.35622318 | Q18: =P18 -> 0.35622318 | S18: =INDEX(Calculation!AB20:AB$34,Calculation!$D$5) -> 0.46976744 | T18: =IF(S18="","",IF(S18>=0.05,"▲",IF(S18<-0.05,"▼",""))) -> ▲ | V18: =INDEX(Calculation!Q20:Q$34,Calculation!$D$5) -> 4828 | X18: =INDEX(Calculation!Z20:Z$34,Calculation!$D$5) -> -0.18720539 | Y18: =X18 -> -0.18720539 | AA18: =INDEX(Calculation!AC20:AC$34,Calculation!$D$5) -> -0.37654959 | AB18: =IF(AA18="","",IF(AA18>=0.05,"▲",IF(AA18<-0.05,"▼",""))) -> ▼
D19: =INDEX(Calculation!M21:M$34,Calculation!$D$5) -> 7 | E19: =INDEX(Calculation!N21:N$34,Calculation!$D$5) -> Minor Liar | F19: =INDEX(Calculation!O21:O$34,Calculation!$D$5) -> 23736.9 | H19: =INDEX(Calculation!X21:X$34,Calculation!$D$5) -> 0.043169293 | I19: =H19 -> 0.043169293 | K19: =INDEX(Calculation!AA21:AA$34,Calculation!$D$5) -> 0.053765016 | L19: =IF(K19="","",IF(K19>=0.05,"▲",IF(K19<-0.05,"▼",""))) -> ▲ | N19: =INDEX(Calculation!P21:P$34,Calculation!$D$5) -> 1012 | P19: =INDEX(Calculation!Y21:Y$34,Calculation!$D$5) -> 0.40888208 | Q19: =P19 -> 0.40888208 | S19: =INDEX(Calculation!AB21:AB$34,Calculation!$D$5) -> 0.39817629 | T19: =IF(S19="","",IF(S19>=0.05,"▲",IF(S19<-0.05,"▼",""))) -> ▲ | V19: =INDEX(Calculation!Q21:Q$34,Calculation!$D$5) -> 8207.1 | X19: =INDEX(Calculation!Z21:Z$34,Calculation!$D$5) -> -0.13133077 | Y19: =X19 -> -0.13133077 | AA19: =INDEX(Calculation!AC21:AC$34,Calculation!$D$5) -> -0.018547751 | AB19: =IF(AA19="","",IF(AA19>=0.05,"▲",IF(AA19<-0.05,"▼","")))
D20: =INDEX(Calculation!M22:M$34,Calculation!$D$5) -> 8 | E20: =INDEX(Calculation!N22:N$34,Calculation!$D$5) -> Mosquit | F20: =INDEX(Calculation!O22:O$34,Calculation!$D$5) -> 6302 | H20: =INDEX(Calculation!X22:X$34,Calculation!$D$5) -> 0.16703704 | I20: =H20 -> 0.16703704 | K20: =INDEX(Calculation!AA22:AA$34,Calculation!$D$5) -> 0.19062913 | L20: =IF(K20="","",IF(K20>=0.05,"▲",IF(K20<-0.05,"▼",""))) -> ▲ | N20: =INDEX(Calculation!P22:P$34,Calculation!$D$5) -> 240 | P20: =INDEX(Calculation!Y22:Y$34,Calculation!$D$5) -> 0.26315789 | Q20: =P20 -> 0.26315789 | S20: =INDEX(Calculation!AB22:AB$34,Calculation!$D$5) -> 0.53846154 | T20: =IF(S20="","",IF(S20>=0.05,"▲",IF(S20<-0.05,"▼",""))) -> ▲ | V20: =INDEX(Calculation!Q22:Q$34,Calculation!$D$5) -> 4655 | X20: =INDEX(Calculation!Z22:Z$34,Calculation!$D$5) -> 0.13647461 | Y20: =X20 -> 0.13647461 | AA20: =INDEX(Calculation!AC22:AC$34,Calculation!$D$5) -> 0.031236154 | AB20: =IF(AA20="","",IF(AA20>=0.05,"▲",IF(AA20<-0.05,"▼","")))
D21: =INDEX(Calculation!M23:M$34,Calculation!$D$5) -> 9 | E21: =INDEX(Calculation!N23:N$34,Calculation!$D$5) -> Atmos | F21: =INDEX(Calculation!O23:O$34,Calculation!$D$5) -> 10675 | H21: =INDEX(Calculation!X23:X$34,Calculation!$D$5) -> 0.053488602 | I21: =H21 -> 0.053488602 | K21: =INDEX(Calculation!AA23:AA$34,Calculation!$D$5) -> -0.044999105 | L21: =IF(K21="","",IF(K21>=0.05,"▲",IF(K21<-0.05,"▼",""))) | N21: =INDEX(Calculation!P23:P$34,Calculation!$D$5) -> 128 | P21: =INDEX(Calculation!Y23:Y$34,Calculation!$D$5) -> 0.43820225 | Q21: =P21 -> 0.43820225 | S21: =INDEX(Calculation!AB23:AB$34,Calculation!$D$5) -> -0.32631579 | T21: =IF(S21="","",IF(S21>=0.05,"▲",IF(S21<-0.05,"▼",""))) -> ▼ | V21: =INDEX(Calculation!Q23:Q$34,Calculation!$D$5) -> 8210 | X21: =INDEX(Calculation!Z23:Z$34,Calculation!$D$5) -> 0.0037901944 | Y21: =X21 -> 0.0037901944 | AA21: =INDEX(Calculation!AC23:AC$34,Calculation!$D$5) -> 0.024968789 | AB21: =IF(AA21="","",IF(AA21>=0.05,"▲",IF(AA21<-0.05,"▼","")))
D22: =INDEX(Calculation!M24:M$34,Calculation!$D$5) -> 10 | E22: =INDEX(Calculation!N24:N$34,Calculation!$D$5) -> Scrap | F22: =INDEX(Calculation!O24:O$34,Calculation!$D$5) -> 13307 | H22: =INDEX(Calculation!X24:X$34,Calculation!$D$5) -> 0.097303538 | I22: =H22 -> 0.097303538 | K22: =INDEX(Calculation!AA24:AA$34,Calculation!$D$5) -> -0.01048483 | L22: =IF(K22="","",IF(K22>=0.05,"▲",IF(K22<-0.05,"▼",""))) | N22: =INDEX(Calculation!P24:P$34,Calculation!$D$5) -> 862 | P22: =INDEX(Calculation!Y24:Y$34,Calculation!$D$5) -> 0.16172507 | Q22: =P22 -> 0.16172507 | S22: =INDEX(Calculation!AB24:AB$34,Calculation!$D$5) -> -0.047513812 | T22: =IF(S22="","",IF(S22>=0.05,"▲",IF(S22<-0.05,"▼",""))) | V22: =INDEX(Calculation!Q24:Q$34,Calculation!$D$5) -> 5279 | X22: =INDEX(Calculation!Z24:Z$34,Calculation!$D$5) -> -0.038608632 | Y22: =X22 -> -0.038608632 | AA22: =INDEX(Calculation!AC24:AC$34,Calculation!$D$5) -> -0.12916529 | AB22: =IF(AA22="","",IF(AA22>=0.05,"▲",IF(AA22<-0.05,"▼",""))) -> ▼

Sheet Calculation
B2: Selected Information (Form controls) | M2: Calculations for scrolling table | AF2: Top 6 / Bottom 6 by KPI | AP2: Profit Line chart | AV2: Data preparation for chart
C4: Selected Division | D4: 3
C5: Table Scroll Position | D5: 1
C6: KPI selection | D6: 1
C7: Top / Bottom Selection | D7: 1
C8: Profit Scroll Position | D8: 1 | O8: =O9&O10&O11&O12 -> 2017JunActualRevenue | P8: =P9&P10&P11&P12 -> 2017JunActualProfit | Q8: =Q9&Q10&Q11&Q12 -> 2017JunActualCash | R8: =R9&R10&R11&R12 -> 2016JunActualRevenue | S8: =S9&S10&S11&S12 -> 2016JunActualProfit | T8: =T9&T10&T11&T12 -> 2016JunActualCash | U8: =U9&U10&U11&U12 -> 2017JunBudgetRevenue | V8: =V9&V10&V11&V12 -> 2017JunBudgetProfit | W8: =W9&W10&W11&W12 -> 2017JunBudgetCash
C9: PY Checkbox | D9: TRUE | O9: =cur_year -> 2017 | P9: =cur_year -> 2017 | Q9: =cur_year -> 2017 | R9: =cur_year-1 -> 2016 | S9: =cur_year-1 -> 2016 | T9: =cur_year-1 -> 2016 | U9: =cur_year -> 2017 | V9: =cur_year -> 2017 | W9: =cur_year -> 2017
C10: Budget Checkbox | D10: TRUE | O10: =cur_month -> Jun | P10: =cur_month -> Jun | Q10: =cur_month -> Jun | R10: =cur_month -> Jun | S10: =cur_month -> Jun | T10: =cur_month -> Jun | U10: =cur_month -> Jun | V10: =cur_month -> Jun | W10: =cur_month -> Jun
O11: Actual | P11: Actual | Q11: Actual | R11: Actual | S11: Actual | T11: Actual | U11: Budget | V11: Budget | W11: Budget | AP11: =INDEX(G14:I34,D8,D4) -> Utility Apps | AV11: ="Profit for "&AP11 -> Profit for Utility Apps
O12: =O14 -> Revenue | P12: =P14 -> Profit | Q12: =Q14 -> Cash | R12: =R14 -> Revenue | S12: =S14 -> Profit | T12: =T14 -> Cash | U12: =U14 -> Revenue | V12: =V14 -> Profit | W12: =W14 -> Cash | AJ12: =CHOOSE(D7,"Top 6","Bottom 6")& " sorted based on % ∆ B" -> Top 6 sorted based on % ∆ B
B13: For Drop-down selections | G13: App to Division Allocation | O13: Actual | R13: PY | U13: Budget | X13: Variance Actual to PY | AA13: Variance Actual to Budget | AF13: Basis - Unsorted | AI13: Sorted | AJ13: ="Actual "&INDEX(O14:Q14,D6)&" Vs. Budget" -> Actual Revenue Vs. Budget | AQ13: =cur_year -> 2017 | AR13: =AQ13-1 -> 2016 | AS13: =AQ13 -> 2017 | AW13: =AQ13 -> 2017 | AX13: =AR13 -> 2016 | AY13: =AS13 -> 2017 | AZ13: Label position
G14: {=TRANSPOSE(C15:C17)} -> Productivity Apps | H14: Game Apps | I14: Utility Apps | M14: Nr. | N14: App | O14: Revenue | P14: Profit | Q14: Cash | R14: Revenue | S14: Profit | T14: Cash | U14: Revenue | V14: Profit | W14: Cash | X14: Revenue% | Y14: Profit% | Z14: Cash% | AA14: Revenue% | AB14: Profit% | AC14: Cash% | AF14: App | AG14: =INDEX(AA14:AC14,D6)&" ∆ B" -> Revenue% ∆ B | AI14: App | AJ14: Actual | AK14: Budget | AL14: Label Position | AM14: Label shown | AP14: Month | AQ14: Actual | AR14: Actual | AS14: Budget | AV14: Month | AW14: =AQ14 -> Actual | AX14: =AR14 -> Actual | AY14: =AS14 -> Budget | AZ14: Actual
B15: Jan | C15: Productivity Apps | D15: Revenue | G15: WenCaL | H15: Fightrr | I15: Commuta | M15: =IF(N15<>"",ROW(A1),"") -> 1 | N15: =IF(INDEX(G15:I15,$D$4)="","",INDEX(G15:I15,$D$4)) -> Commuta | O15: =IF($N15<>"",INDEX(Data!$B$9:$J$60,MATCH($N15,Data!$A$9:$A$60,0),MATCH(O$8,Data!$B$4:$J$4,0)),"") -> 6353 | P15: =IF($N15<>"",INDEX(Data!$B$9:$J$60,MATCH($N15,Data!$A$9:$A$60,0),MATCH(P$8,Data!$B$4:$J$4,0)),"") -> 762 | Q15: =IF($N15<>"",INDEX(Data!$B$9:$J$60,MATCH($N15,Data!$A$9:$A$60,0),MATCH(Q$8,Data!$B$4:$J$4,0)),"") -> 7332 | R15: =IF($N15<>"",INDEX(Data!$B$9:$J$60,MATCH($N15,Data!$A$9:$A$60,0),MATCH(R$8,Data!$B$4:$J$4,0)),"") -> 5993 | S15: =IF($N15<>"",INDEX(Data!$B$9:$J$60,MATCH($N15,Data!$A$9:$A$60,0),MATCH(S$8,Data!$B$4:$J$4,0)),"") -> 674 | T15: =IF($N15<>"",INDEX(Data!$B$9:$J$60,MATCH($N15,Data!$A$9:$A$60,0),MATCH(T$8,Data!$B$4:$J$4,0)),"") -> 7167 | U15: =IF($N15<>"",INDEX(Data!$B$9:$J$60,MATCH($N15,Data!$A$9:$A$60,0),MATCH(U$8,Data!$B$4:$J$4,0)),"") -> 5275 | V15: =IF($N15<>"",INDEX(Data!$B$9:$J$60,MATCH($N15,Data!$A$9:$A$60,0),MATCH(V$8,Data!$B$4:$J$4,0)),"") -> 568 | W15: =IF($N15<>"",INDEX(Data!$B$9:$J$60,MATCH($N15,Data!$A$9:$A$60,0),MATCH(W$8,Data!$B$4:$J$4,0)),"") -> 7227 | X15: =IF($N15<>"",(O15-R15)/R15,"") -> 0.060070082 | Y15: =IF($N15<>"",(P15-S15)/S15,"") -> 0.1305638 | Z15: =IF($N15<>"",(Q15-T15)/T15,"") -> 0.023022185 | AA15: =IF($N15<>"",(O15-U15)/U15,"") -> 0.20436019 | AB15: =IF($N15<>"",(P15-V15)/V15,"") -> 0.3415493 | AC15: =IF($N15<>"",(Q15-W15)/W15,"") -> 0.01452885 | AF15: =N15 -> Commuta | AG15: =IF(AF15="","",INDEX(AA15:AC15,$D$6)+(ROW()/10000000000)+N("the row function is used here to make sure we have unique values to sort")) -> 0.20436019 | AI15: =INDEX($AF$15:$AF$34,MATCH(CHOOSE($D$7,LARGE($AG$15:$AG$34,$M15),SMALL($AG$15:$AG$34,$M15)),$AG$15:$AG$34,0)) -> Commuta | AJ15: =INDEX($O$15:$Q$35,MATCH($AI15,$N$15:$N$34,0),$D$6) -> 6353 | AK15: =INDEX($U$15:$W$35,MATCH($AI15,$N$15:$N$34,0),$D$6) -> 5275 | AL15: =MAX(AJ15:AK15) -> 6353 | AM15: =TEXT(INDEX($AA$15:$AC$34,MATCH(AI15,$N$15:$N$34,0),$D$6),"0%")&" | "&TEXT(AJ15,"#,##0") -> 20% | 6,353 | AP15: Jan | AQ15: =INDEX(Data!$K$9:$AT$60,MATCH(Calculation!$AP$11,Data!$A$9:$A$60,0),MATCH(Calculation!AQ$13&Calculation!$AP15&Calculation!AQ$14,INDEX(Data!$K$5:$AT$5&Data!$K$6:$AT$6&Data!$K$7:$AT$7,),0)) -> 1232.6 | AR15: =INDEX(Data!$K$9:$AT$60,MATCH(Calculation!$AP$11,Data!$A$9:$A$60,0),MATCH(Calculation!AR$13&Calculation!$AP15&Calculation!AR$14,INDEX(Data!$K$5:$AT$5&Data!$K$6:$AT$6&Data!$K$7:$AT$7,),0)) -> 1081.8 | AS15: =INDEX(Data!$K$9:$AT$60,MATCH(Calculation!$AP$11,Data!$A$9:$A$60,0),MATCH(Calculation!AS$13&Calculation!$AP15&Calculation!AS$14,INDEX(Data!$K$5:$AT$5&Data!$K$6:$AT$6&Data!$K$7:$AT$7,),0)) -> 1097.7 | AV15: =LEFT(AP15,1) -> J | AW15: =IF(MATCH(cur_month,$AP$15:$AP$26,0)>=ROWS($AP$15:AP15),AQ15,NA()) -> 1232.6 | AX15: =IF($D$9,AR15,NA()) -> 1081.8 | AY15: =IF($D$10,AS15,NA()) -> 1097.7 | AZ15: =IF(AP15=cur_month,AW15,NA()) -> #N/A
B16: Feb | C16: Game Apps | D16: Profit | G16: Blend | H16: Kryptis | I16: Infic | M16: =IF(N16<>"",ROW(A2),"") -> 2 | N16: =IF(INDEX(G16:I16,$D$4)="","",INDEX(G16:I16,$D$4)) -> Infic | O16: =IF($N16<>"",INDEX(Data!$B$9:$J$60,MATCH($N16,Data!$A$9:$A$60,0),MATCH(O$8,Data!$B$4:$J$4,0)),"") -> 12373 | P16: =IF($N16<>"",INDEX(Data!$B$9:$J$60,MATCH($N16,Data!$A$9:$A$60,0),MATCH(P$8,Data!$B$4:$J$4,0)),"") -> 408 | Q16: =IF($N16<>"",INDEX(Data!$B$9:$J$60,MATCH($N16,Data!$A$9:$A$60,0),MATCH(Q$8,Data!$B$4:$J$4,0)),"") -> 3054 | R16: =IF($N16<>"",INDEX(Data!$B$9:$J$60,MATCH($N16,Data!$A$9:$A$60,0),MATCH(R$8,Data!$B$4:$J$4,0)),"") -> 12398 | S16: =IF($N16<>"",INDEX(Data!$B$9:$J$60,MATCH($N16,Data!$A$9:$A$60,0),MATCH(S$8,Data!$B$4:$J$4,0)),"") -> 341 | T16: =IF($N16<>"",INDEX(Data!$B$9:$J$60,MATCH($N16,Data!$A$9:$A$60,0),MATCH(T$8,Data!$B$4:$J$4,0)),"") -> 3033 | U16: =IF($N16<>"",INDEX(Data!$B$9:$J$60,MATCH($N16,Data!$A$9:$A$60,0),MATCH(U$8,Data!$B$4:$J$4,0)),"") -> 10472 | V16: =IF($N16<>"",INDEX(Data!$B$9:$J$60,MATCH($N16,Data!$A$9:$A$60,0),MATCH(V$8,Data!$B$4:$J$4,0)),"") -> 461 | W16: =IF($N16<>"",INDEX(Data!$B$9:$J$60,MATCH($N16,Data!$A$9:$A$60,0),MATCH(W$8,Data!$B$4:$J$4,0)),"") -> 2910 | X16: =IF($N16<>"",(O16-R16)/R16,"") -> -0.0020164543 | Y16: =IF($N16<>"",(P16-S16)/S16,"") -> 0.19648094 | Z16: =IF($N16<>"",(Q16-T16)/T16,"") -> 0.0069238378 | AA16: =IF($N16<>"",(O16-U16)/U16,"") -> 0.1815317 | AB16: =IF($N16<>"",(P16-V16)/V16,"") -> -0.11496746 | AC16: =IF($N16<>"",(Q16-W16)/W16,"") -> 0.049484536 | AF16: =N16 -> Infic | AG16: =IF(AF16="","",INDEX(AA16:AC16,$D$6)+(ROW()/10000000000)+N("the row function is used here to make sure we have unique values to sort")) -> 0.18153171 | AI16: =INDEX($AF$15:$AF$34,MATCH(CHOOSE($D$7,LARGE($AG$15:$AG$34,$M16),SMALL($AG$15:$AG$34,$M16)),$AG$15:$AG$34,0)) -> Mosquit | AJ16: =INDEX($O$15:$Q$35,MATCH($AI16,$N$15:$N$34,0),$D$6) -> 6302 | AK16: =INDEX($U$15:$W$35,MATCH($AI16,$N$15:$N$34,0),$D$6) -> 5293 | AL16: =MAX(AJ16:AK16) -> 6302 | AM16: =TEXT(INDEX($AA$15:$AC$34,MATCH(AI16,$N$15:$N$34,0),$D$6),"0%")&" | "&TEXT(AJ16,"#,##0") -> 19% | 6,302 | AP16: Feb | AQ16: =INDEX(Data!$K$9:$AT$60,MATCH(Calculation!$AP$11,Data!$A$9:$A$60,0),MATCH(Calculation!AQ$13&Calculation!$AP16&Calculation!AQ$14,INDEX(Data!$K$5:$AT$5&Data!$K$6:$AT$6&Data!$K$7:$AT$7,),0)) -> 2521.8 | AR16: =INDEX(Data!$K$9:$AT$60,MATCH(Calculation!$AP$11,Data!$A$9:$A$60,0),MATCH(Calculation!AR$13&Calculation!$AP16&Calculation!AR$14,INDEX(Data!$K$5:$AT$5&Data!$K$6:$AT$6&Data!$K$7:$AT$7,),0)) -> 1914.2 | AS16: =INDEX(Data!$K$9:$AT$60,MATCH(Calculation!$AP$11,Data!$A$9:$A$60,0),MATCH(Calculation!AS$13&Calculation!$AP16&Calculation!AS$14,INDEX(Data!$K$5:$AT$5&Data!$K$6:$AT$6&Data!$K$7:$AT$7,),0)) -> 2174.8 | AV16: =LEFT(AP16,1) -> F | AW16: =IF(MATCH(cur_month,$AP$15:$AP$26,0)>=ROWS($AP$15:AP16),AQ16,NA()) -> 2521.8 | AX16: =IF($D$9,AR16,NA()) -> 1914.2 | AY16: =IF($D$10,AS16,NA()) -> 2174.8 | AZ16: =IF(AP16=cur_month,AW16,NA()) -> #N/A
B17: Mar | C17: Utility Apps | D17: Cash | G17: Voltage | H17: Perino | I17: Accord | M17: =IF(N17<>"",ROW(A3),"") -> 3 | N17: =IF(INDEX(G17:I17,$D$4)="","",INDEX(G17:I17,$D$4)) -> Accord | O17: =IF($N17<>"",INDEX(Data!$B$9:$J$60,MATCH($N17,Data!$A$9:$A$60,0),MATCH(O$8,Data!$B$4:$J$4,0)),"") -> 17760 | P17: =IF($N17<>"",INDEX(Data!$B$9:$J$60,MATCH($N17,Data!$A$9:$A$60,0),MATCH(P$8,Data!$B$4:$J$4,0)),"") -> 800 | Q17: =IF($N17<>"",INDEX(Data!$B$9:$J$60,MATCH($N17,Data!$A$9:$A$60,0),MATCH(Q$8,Data!$B$4:$J$4,0)),"") -> 6488 | R17: =IF($N17<>"",INDEX(Data!$B$9:$J$60,MATCH($N17,Data!$A$9:$A$60,0),MATCH(R$8,Data!$B$4:$J$4,0)),"") -> 17025 | S17: =IF($N17<>"",INDEX(Data!$B$9:$J$60,MATCH($N17,Data!$A$9:$A$60,0),MATCH(S$8,Data!$B$4:$J$4,0)),"") -> 568 | T17: =IF($N17<>"",INDEX(Data!$B$9:$J$60,MATCH($N17,Data!$A$9:$A$60,0),MATCH(T$8,Data!$B$4:$J$4,0)),"") -> 7469 | U17: =IF($N17<>"",INDEX(Data!$B$9:$J$60,MATCH($N17,Data!$A$9:$A$60,0),MATCH(U$8,Data!$B$4:$J$4,0)),"") -> 16854 | V17: =IF($N17<>"",INDEX(Data!$B$9:$J$60,MATCH($N17,Data!$A$9:$A$60,0),MATCH(V$8,Data!$B$4:$J$4,0)),"") -> 572 | W17: =IF($N17<>"",INDEX(Data!$B$9:$J$60,MATCH($N17,Data!$A$9:$A$60,0),MATCH(W$8,Data!$B$4:$J$4,0)),"") -> 6611 | X17: =IF($N17<>"",(O17-R17)/R17,"") -> 0.043171806 | Y17: =IF($N17<>"",(P17-S17)/S17,"") -> 0.4084507 | Z17: =IF($N17<>"",(Q17-T17)/T17,"") -> -0.13134288 | AA17: =IF($N17<>"",(O17-U17)/U17,"") -> 0.053755785 | AB17: =IF($N17<>"",(P17-V17)/V17,"") -> 0.3986014 | AC17: =IF($N17<>"",(Q17-W17)/W17,"") -> -0.018605355 | AF17: =N17 -> Accord | AG17: =IF(AF17="","",INDEX(AA17:AC17,$D$6)+(ROW()/10000000000)+N("the row function is used here to make sure we have unique values to sort")) -> 0.053755787 | AI17: =INDEX($AF$15:$AF$34,MATCH(CHOOSE($D$7,LARGE($AG$15:$AG$34,$M17),SMALL($AG$15:$AG$34,$M17)),$AG$15:$AG$34,0)) -> Infic | AJ17: =INDEX($O$15:$Q$35,MATCH($AI17,$N$15:$N$34,0),$D$6) -> 12373 | AK17: =INDEX($U$15:$W$35,MATCH($AI17,$N$15:$N$34,0),$D$6) -> 10472 | AL17: =MAX(AJ17:AK17) -> 12373 | AM17: =TEXT(INDEX($AA$15:$AC$34,MATCH(AI17,$N$15:$N$34,0),$D$6),"0%")&" | "&TEXT(AJ17,"#,##0") -> 18% | 12,373 | AP17: Mar | AQ17: =INDEX(Data!$K$9:$AT$60,MATCH(Calculation!$AP$11,Data!$A$9:$A$60,0),MATCH(Calculation!AQ$13&Calculation!$AP17&Calculation!AQ$14,INDEX(Data!$K$5:$AT$5&Data!$K$6:$AT$6&Data!$K$7:$AT$7,),0)) -> 3867.8 | AR17: =INDEX(Data!$K$9:$AT$60,MATCH(Calculation!$AP$11,Data!$A$9:$A$60,0),MATCH(Calculation!AR$13&Calculation!$AP17&Calculation!AR$14,INDEX(Data!$K$5:$AT$5&Data!$K$6:$AT$6&Data!$K$7:$AT$7,),0)) -> 3013.9 | AS17: =INDEX(Data!$K$9:$AT$60,MATCH(Calculation!$AP$11,Data!$A$9:$A$60,0),MATCH(Calculation!AS$13&Calculation!$AP17&Calculation!AS$14,INDEX(Data!$K$5:$AT$5&Data!$K$6:$AT$6&Data!$K$7:$AT$7,),0)) -> 3533.9 | AV17: =LEFT(AP17,1) -> M | AW17: =IF(MATCH(cur_month,$AP$15:$AP$26,0)>=ROWS($AP$15:AP17),AQ17,NA()) -> 3867.8 | AX17: =IF($D$9,AR17,NA()) -> 3013.9 | AY17: =IF($D$10,AS17,NA()) -> 3533.9 | AZ17: =IF(AP17=cur_month,AW17,NA()) -> #N/A
B18: Apr | G18: Inkly | H18: Five Labs | I18: Misty Wash | M18: =IF(N18<>"",ROW(A4),"") -> 4 | N18: =IF(INDEX(G18:I18,$D$4)="","",INDEX(G18:I18,$D$4)) -> Misty Wash | O18: =IF($N18<>"",INDEX(Data!$B$9:$J$60,MATCH($N18,Data!$A$9:$A$60,0),MATCH(O$8,Data!$B$4:$J$4,0)),"") -> 30399.6 | P18: =IF($N18<>"",INDEX(Data!$B$9:$J$60,MATCH($N18,Data!$A$9:$A$60,0),MATCH(P$8,Data!$B$4:$J$4,0)),"") -> 786.8 | Q18: =IF($N18<>"",INDEX(Data!$B$9:$J$60,MATCH($N18,Data!$A$9:$A$60,0),MATCH(Q$8,Data!$B$4:$J$4,0)),"") -> 12308.8 | R18: =IF($N18<>"",INDEX(Data!$B$9:$J$60,MATCH($N18,Data!$A$9:$A$60,0),MATCH(R$8,Data!$B$4:$J$4,0)),"") -> 29531.6 | S18: =IF($N18<>"",INDEX(Data!$B$9:$J$60,MATCH($N18,Data!$A$9:$A$60,0),MATCH(S$8,Data!$B$4:$J$4,0)),"") -> 786.8 | T18: =IF($N18<>"",INDEX(Data!$B$9:$J$60,MATCH($N18,Data!$A$9:$A$60,0),MATCH(T$8,Data!$B$4:$J$4,0)),"") -> 13941.2 | U18: =IF($N18<>"",INDEX(Data!$B$9:$J$60,MATCH($N18,Data!$A$9:$A$60,0),MATCH(U$8,Data!$B$4:$J$4,0)),"") -> 30237.2 | V18: =IF($N18<>"",INDEX(Data!$B$9:$J$60,MATCH($N18,Data!$A$9:$A$60,0),MATCH(V$8,Data!$B$4:$J$4,0)),"") -> 932.4 | W18: =IF($N18<>"",INDEX(Data!$B$9:$J$60,MATCH($N18,Data!$A$9:$A$60,0),MATCH(W$8,Data!$B$4:$J$4,0)),"") -> 13381.2 | X18: =IF($N18<>"",(O18-R18)/R18,"") -> 0.029392244 | Y18: =IF($N18<>"",(P18-S18)/S18,"") -> 0 | Z18: =IF($N18<>"",(Q18-T18)/T18,"") -> -0.11709179 | AA18: =IF($N18<>"",(O18-U18)/U18,"") -> 0.0053708677 | AB18: =IF($N18<>"",(P18-V18)/V18,"") -> -0.15615616 | AC18: =IF($N18<>"",(Q18-W18)/W18,"") -> -0.080142289 | AF18: =N18 -> Misty Wash | AG18: =IF(AF18="","",INDEX(AA18:AC18,$D$6)+(ROW()/10000000000)+N("the row function is used here to make sure we have unique values to sort")) -> 0.0053708695 | AI18: =INDEX($AF$15:$AF$34,MATCH(CHOOSE($D$7,LARGE($AG$15:$AG$34,$M18),SMALL($AG$15:$AG$34,$M18)),$AG$15:$AG$34,0)) -> Motocyco | AJ18: =INDEX($O$15:$Q$35,MATCH($AI18,$N$15:$N$34,0),$D$6) -> 11182 | AK18: =INDEX($U$15:$W$35,MATCH($AI18,$N$15:$N$34,0),$D$6) -> 9952 | AL18: =MAX(AJ18:AK18) -> 11182 | AM18: =TEXT(INDEX($AA$15:$AC$34,MATCH(AI18,$N$15:$N$34,0),$D$6),"0%")&" | "&TEXT(AJ18,"#,##0") -> 12% | 11,182 | AP18: Apr | AQ18: =INDEX(Data!$K$9:$AT$60,MATCH(Calculation!$AP$11,Data!$A$9:$A$60,0),MATCH(Calculation!AQ$13&Calculation!$AP18&Calculation!AQ$14,INDEX(Data!$K$5:$AT$5&Data!$K$6:$AT$6&Data!$K$7:$AT$7,),0)) -> 5348.4 | AR18: =INDEX(Data!$K$9:$AT$60,MATCH(Calculation!$AP$11,Data!$A$9:$A$60,0),MATCH(Calculation!AR$13&Calculation!$AP18&Calculation!AR$14,INDEX(Data!$K$5:$AT$5&Data!$K$6:$AT$6&Data!$K$7:$AT$7,),0)) -> 4416.4 | AS18: =INDEX(Data!$K$9:$AT$60,MATCH(Calculation!$AP$11,Data!$A$9:$A$60,0),MATCH(Calculation!AS$13&Calculation!$AP18&Calculation!AS$14,INDEX(Data!$K$5:$AT$5&Data!$K$6:$AT$6&Data!$K$7:$AT$7,),0)) -> 4717.1 | AV18: =LEFT(AP18,1) -> A | AW18: =IF(MATCH(cur_month,$AP$15:$AP$26,0)>=ROWS($AP$15:AP18),AQ18,NA()) -> 5348.4 | AX18: =IF($D$9,AR18,NA()) -> 4416.4 | AY18: =IF($D$10,AS18,NA()) -> 4717.1 | AZ18: =IF(AP18=cur_month,AW18,NA()) -> #N/A
B19: May | G19: Sleops | H19: Twistrr | I19: Twenty20 | M19: =IF(N19<>"",ROW(A5),"") -> 5 | N19: =IF(INDEX(G19:I19,$D$4)="","",INDEX(G19:I19,$D$4)) -> Twenty20 | O19: =IF($N19<>"",INDEX(Data!$B$9:$J$60,MATCH($N19,Data!$A$9:$A$60,0),MATCH(O$8,Data!$B$4:$J$4,0)),"") -> 20400 | P19: =IF($N19<>"",INDEX(Data!$B$9:$J$60,MATCH($N19,Data!$A$9:$A$60,0),MATCH(P$8,Data!$B$4:$J$4,0)),"") -> 614.4 | Q19: =IF($N19<>"",INDEX(Data!$B$9:$J$60,MATCH($N19,Data!$A$9:$A$60,0),MATCH(Q$8,Data!$B$4:$J$4,0)),"") -> 15171.2 | R19: =IF($N19<>"",INDEX(Data!$B$9:$J$60,MATCH($N19,Data!$A$9:$A$60,0),MATCH(R$8,Data!$B$4:$J$4,0)),"") -> 22224 | S19: =IF($N19<>"",INDEX(Data!$B$9:$J$60,MATCH($N19,Data!$A$9:$A$60,0),MATCH(S$8,Data!$B$4:$J$4,0)),"") -> 988.8 | T19: =IF($N19<>"",INDEX(Data!$B$9:$J$60,MATCH($N19,Data!$A$9:$A$60,0),MATCH(T$8,Data!$B$4:$J$4,0)),"") -> 16019.2 | U19: =IF($N19<>"",INDEX(Data!$B$9:$J$60,MATCH($N19,Data!$A$9:$A$60,0),MATCH(U$8,Data!$B$4:$J$4,0)),"") -> 18476.8 | V19: =IF($N19<>"",INDEX(Data!$B$9:$J$60,MATCH($N19,Data!$A$9:$A$60,0),MATCH(V$8,Data!$B$4:$J$4,0)),"") -> 1120 | W19: =IF($N19<>"",INDEX(Data!$B$9:$J$60,MATCH($N19,Data!$A$9:$A$60,0),MATCH(W$8,Data!$B$4:$J$4,0)),"") -> 14230.4 | X19: =IF($N19<>"",(O19-R19)/R19,"") -> -0.082073434 | Y19: =IF($N19<>"",(P19-S19)/S19,"") -> -0.37864078 | Z19: =IF($N19<>"",(Q19-T19)/T19,"") -> -0.052936476 | AA19: =IF($N19<>"",(O19-U19)/U19,"") -> 0.10408729 | AB19: =IF($N19<>"",(P19-V19)/V19,"") -> -0.45142857 | AC19: =IF($N19<>"",(Q19-W19)/W19,"") -> 0.066111986 | AF19: =N19 -> Twenty20 | AG19: =IF(AF19="","",INDEX(AA19:AC19,$D$6)+(ROW()/10000000000)+N("the row function is used here to make sure we have unique values to sort")) -> 0.10408729 | AI19: =INDEX($AF$15:$AF$34,MATCH(CHOOSE($D$7,LARGE($AG$15:$AG$34,$M19),SMALL($AG$15:$AG$34,$M19)),$AG$15:$AG$34,0)) -> Twenty20 | AJ19: =INDEX($O$15:$Q$35,MATCH($AI19,$N$15:$N$34,0),$D$6) -> 20400 | AK19: =INDEX($U$15:$W$35,MATCH($AI19,$N$15:$N$34,0),$D$6) -> 18476.8 | AL19: =MAX(AJ19:AK19) -> 20400 | AM19: =TEXT(INDEX($AA$15:$AC$34,MATCH(AI19,$N$15:$N$34,0),$D$6),"0%")&" | "&TEXT(AJ19,"#,##0") -> 10% | 20,400 | AP19: May | AQ19: =INDEX(Data!$K$9:$AT$60,MATCH(Calculation!$AP$11,Data!$A$9:$A$60,0),MATCH(Calculation!AQ$13&Calculation!$AP19&Calculation!AQ$14,INDEX(Data!$K$5:$AT$5&Data!$K$6:$AT$6&Data!$K$7:$AT$7,),0)) -> 7289.8 | AR19: =INDEX(Data!$K$9:$AT$60,MATCH(Calculation!$AP$11,Data!$A$9:$A$60,0),MATCH(Calculation!AR$13&Calculation!$AP19&Calculation!AR$14,INDEX(Data!$K$5:$AT$5&Data!$K$6:$AT$6&Data!$K$7:$AT$7,),0)) -> 5770.1 | AS19: =INDEX(Data!$K$9:$AT$60,MATCH(Calculation!$AP$11,Data!$A$9:$A$60,0),MATCH(Calculation!AS$13&Calculation!$AP19&Calculation!AS$14,INDEX(Data!$K$5:$AT$5&Data!$K$6:$AT$6&Data!$K$7:$AT$7,),0)) -> 6398.8 | AV19: =LEFT(AP19,1) -> M | AW19: =IF(MATCH(cur_month,$AP$15:$AP$26,0)>=ROWS($AP$15:AP19),AQ19,NA()) -> 7289.8 | AX19: =IF($D$9,AR19,NA()) -> 5770.1 | AY19: =IF($D$10,AS19,NA()) -> 6398.8 | AZ19: =IF(AP19=cur_month,AW19,NA()) -> #N/A
B20: Jun | G20: Kind Ape | H20: Hackrr | I20: Tanox | M20: =IF(N20<>"",ROW(A6),"") -> 6 | N20: =IF(INDEX(G20:I20,$D$4)="","",INDEX(G20:I20,$D$4)) -> Tanox | O20: =IF($N20<>"",INDEX(Data!$B$9:$J$60,MATCH($N20,Data!$A$9:$A$60,0),MATCH(O$8,Data!$B$4:$J$4,0)),"") -> 21088 | P20: =IF($N20<>"",INDEX(Data!$B$9:$J$60,MATCH($N20,Data!$A$9:$A$60,0),MATCH(P$8,Data!$B$4:$J$4,0)),"") -> 1264 | Q20: =IF($N20<>"",INDEX(Data!$B$9:$J$60,MATCH($N20,Data!$A$9:$A$60,0),MATCH(Q$8,Data!$B$4:$J$4,0)),"") -> 4828 | R20: =IF($N20<>"",INDEX(Data!$B$9:$J$60,MATCH($N20,Data!$A$9:$A$60,0),MATCH(R$8,Data!$B$4:$J$4,0)),"") -> 19736 | S20: =IF($N20<>"",INDEX(Data!$B$9:$J$60,MATCH($N20,Data!$A$9:$A$60,0),MATCH(S$8,Data!$B$4:$J$4,0)),"") -> 932 | T20: =IF($N20<>"",INDEX(Data!$B$9:$J$60,MATCH($N20,Data!$A$9:$A$60,0),MATCH(T$8,Data!$B$4:$J$4,0)),"") -> 5940 | U20: =IF($N20<>"",INDEX(Data!$B$9:$J$60,MATCH($N20,Data!$A$9:$A$60,0),MATCH(U$8,Data!$B$4:$J$4,0)),"") -> 19156 | V20: =IF($N20<>"",INDEX(Data!$B$9:$J$60,MATCH($N20,Data!$A$9:$A$60,0),MATCH(V$8,Data!$B$4:$J$4,0)),"") -> 860 | W20: =IF($N20<>"",INDEX(Data!$B$9:$J$60,MATCH($N20,Data!$A$9:$A$60,0),MATCH(W$8,Data!$B$4:$J$4,0)),"") -> 7744 | X20: =IF($N20<>"",(O20-R20)/R20,"") -> 0.068504256 | Y20: =IF($N20<>"",(P20-S20)/S20,"") -> 0.35622318 | Z20: =IF($N20<>"",(Q20-T20)/T20,"") -> -0.18720539 | AA20: =IF($N20<>"",(O20-U20)/U20,"") -> 0.10085613 | AB20: =IF($N20<>"",(P20-V20)/V20,"") -> 0.46976744 | AC20: =IF($N20<>"",(Q20-W20)/W20,"") -> -0.37654959 | AF20: =N20 -> Tanox | AG20: =IF(AF20="","",INDEX(AA20:AC20,$D$6)+(ROW()/10000000000)+N("the row function is used here to make sure we have unique values to sort")) -> 0.10085613 | AI20: =INDEX($AF$15:$AF$34,MATCH(CHOOSE($D$7,LARGE($AG$15:$AG$34,$M20),SMALL($AG$15:$AG$34,$M20)),$AG$15:$AG$34,0)) -> Tanox | AJ20: =INDEX($O$15:$Q$35,MATCH($AI20,$N$15:$N$34,0),$D$6) -> 21088 | AK20: =INDEX($U$15:$W$35,MATCH($AI20,$N$15:$N$34,0),$D$6) -> 19156 | AL20: =MAX(AJ20:AK20) -> 21088 | AM20: =TEXT(INDEX($AA$15:$AC$34,MATCH(AI20,$N$15:$N$34,0),$D$6),"0%")&" | "&TEXT(AJ20,"#,##0") -> 10% | 21,088 | AP20: Jun | AQ20: =INDEX(Data!$K$9:$AT$60,MATCH(Calculation!$AP$11,Data!$A$9:$A$60,0),MATCH(Calculation!AQ$13&Calculation!$AP20&Calculation!AQ$14,INDEX(Data!$K$5:$AT$5&Data!$K$6:$AT$6&Data!$K$7:$AT$7,),0)) -> 8869.2 | AR20: =INDEX(Data!$K$9:$AT$60,MATCH(Calculation!$AP$11,Data!$A$9:$A$60,0),MATCH(Calculation!AR$13&Calculation!$AP20&Calculation!AR$14,INDEX(Data!$K$5:$AT$5&Data!$K$6:$AT$6&Data!$K$7:$AT$7,),0)) -> 7247.9 | AS20: =INDEX(Data!$K$9:$AT$60,MATCH(Calculation!$AP$11,Data!$A$9:$A$60,0),MATCH(Calculation!AS$13&Calculation!$AP20&Calculation!AS$14,INDEX(Data!$K$5:$AT$5&Data!$K$6:$AT$6&Data!$K$7:$AT$7,),0)) -> 7933.2 | AV20: =LEFT(AP20,1) -> J | AW20: =IF(MATCH(cur_month,$AP$15:$AP$26,0)>=ROWS($AP$15:AP20),AQ20,NA()) -> 8869.2 | AX20: =IF($D$9,AR20,NA()) -> 7247.9 | AY20: =IF($D$10,AS20,NA()) -> 7933.2 | AZ20: =IF(AP20=cur_month,AW20,NA()) -> 8869.2
B21: Jul | G21: Pet Feed | H21: Pes | I21: Minor Liar | M21: =IF(N21<>"",ROW(A7),"") -> 7 | N21: =IF(INDEX(G21:I21,$D$4)="","",INDEX(G21:I21,$D$4)) -> Minor Liar | O21: =IF($N21<>"",INDEX(Data!$B$9:$J$60,MATCH($N21,Data!$A$9:$A$60,0),MATCH(O$8,Data!$B$4:$J$4,0)),"") -> 23736.9 | P21: =IF($N21<>"",INDEX(Data!$B$9:$J$60,MATCH($N21,Data!$A$9:$A$60,0),MATCH(P$8,Data!$B$4:$J$4,0)),"") -> 1012 | Q21: =IF($N21<>"",INDEX(Data!$B$9:$J$60,MATCH($N21,Data!$A$9:$A$60,0),MATCH(Q$8,Data!$B$4:$J$4,0)),"") -> 8207.1 | R21: =IF($N21<>"",INDEX(Data!$B$9:$J$60,MATCH($N21,Data!$A$9:$A$60,0),MATCH(R$8,Data!$B$4:$J$4,0)),"") -> 22754.6 | S21: =IF($N21<>"",INDEX(Data!$B$9:$J$60,MATCH($N21,Data!$A$9:$A$60,0),MATCH(S$8,Data!$B$4:$J$4,0)),"") -> 718.3 | T21: =IF($N21<>"",INDEX(Data!$B$9:$J$60,MATCH($N21,Data!$A$9:$A$60,0),MATCH(T$8,Data!$B$4:$J$4,0)),"") -> 9447.9 | U21: =IF($N21<>"",INDEX(Data!$B$9:$J$60,MATCH($N21,Data!$A$9:$A$60,0),MATCH(U$8,Data!$B$4:$J$4,0)),"") -> 22525.8 | V21: =IF($N21<>"",INDEX(Data!$B$9:$J$60,MATCH($N21,Data!$A$9:$A$60,0),MATCH(V$8,Data!$B$4:$J$4,0)),"") -> 723.8 | W21: =IF($N21<>"",INDEX(Data!$B$9:$J$60,MATCH($N21,Data!$A$9:$A$60,0),MATCH(W$8,Data!$B$4:$J$4,0)),"") -> 8362.2 | X21: =IF($N21<>"",(O21-R21)/R21,"") -> 0.043169293 | Y21: =IF($N21<>"",(P21-S21)/S21,"") -> 0.40888208 | Z21: =IF($N21<>"",(Q21-T21)/T21,"") -> -0.13133077 | AA21: =IF($N21<>"",(O21-U21)/U21,"") -> 0.053765016 | AB21: =IF($N21<>"",(P21-V21)/V21,"") -> 0.39817629 | AC21: =IF($N21<>"",(Q21-W21)/W21,"") -> -0.018547751 | AF21: =N21 -> Minor Liar | AG21: =IF(AF21="","",INDEX(AA21:AC21,$D$6)+(ROW()/10000000000)+N("the row function is used here to make sure we have unique values to sort")) -> 0.053765018 | AP21: Jul | AQ21: =INDEX(Data!$K$9:$AT$60,MATCH(Calculation!$AP$11,Data!$A$9:$A$60,0),MATCH(Calculation!AQ$13&Calculation!$AP21&Calculation!AQ$14,INDEX(Data!$K$5:$AT$5&Data!$K$6:$AT$6&Data!$K$7:$AT$7,),0)) -> 0 | AR21: =INDEX(Data!$K$9:$AT$60,MATCH(Calculation!$AP$11,Data!$A$9:$A$60,0),MATCH(Calculation!AR$13&Calculation!$AP21&Calculation!AR$14,INDEX(Data!$K$5:$AT$5&Data!$K$6:$AT$6&Data!$K$7:$AT$7,),0)) -> 8752.2 | AS21: =INDEX(Data!$K$9:$AT$60,MATCH(Calculation!$AP$11,Data!$A$9:$A$60,0),MATCH(Calculation!AS$13&Calculation!$AP21&Calculation!AS$14,INDEX(Data!$K$5:$AT$5&Data!$K$6:$AT$6&Data!$K$7:$AT$7,),0)) -> 9431.5 | AV21: =LEFT(AP21,1) -> J | AW21: =IF(MATCH(cur_month,$AP$15:$AP$26,0)>=ROWS($AP$15:AP21),AQ21,NA()) -> #N/A | AX21: =IF($D$9,AR21,NA()) -> 8752.2 | AY21: =IF($D$10,AS21,NA()) -> 9431.5 | AZ21: =IF(AP21=cur_month,AW21,NA()) -> #N/A
B22: Aug | G22: Right App | H22: Baden | I22: Mosquit | M22: =IF(N22<>"",ROW(A8),"") -> 8 | N22: =IF(INDEX(G22:I22,$D$4)="","",INDEX(G22:I22,$D$4)) -> Mosquit | O22: =IF($N22<>"",INDEX(Data!$B$9:$J$60,MATCH($N22,Data!$A$9:$A$60,0),MATCH(O$8,Data!$B$4:$J$4,0)),"") -> 6302 | P22: =IF($N22<>"",INDEX(Data!$B$9:$J$60,MATCH($N22,Data!$A$9:$A$60,0),MATCH(P$8,Data!$B$4:$J$4,0)),"") -> 240 | Q22: =IF($N22<>"",INDEX(Data!$B$9:$J$60,MATCH($N22,Data!$A$9:$A$60,0),MATCH(Q$8,Data!$B$4:$J$4,0)),"") -> 4655 | R22: =IF($N22<>"",INDEX(Data!$B$9:$J$60,MATCH($N22,Data!$A$9:$A$60,0),MATCH(R$8,Data!$B$4:$J$4,0)),"") -> 5400 | S22: =IF($N22<>"",INDEX(Data!$B$9:$J$60,MATCH($N22,Data!$A$9:$A$60,0),MATCH(S$8,Data!$B$4:$J$4,0)),"") -> 190 | T22: =IF($N22<>"",INDEX(Data!$B$9:$J$60,MATCH($N22,Data!$A$9:$A$60,0),MATCH(T$8,Data!$B$4:$J$4,0)),"") -> 4096 | U22: =IF($N22<>"",INDEX(Data!$B$9:$J$60,MATCH($N22,Data!$A$9:$A$60,0),MATCH(U$8,Data!$B$4:$J$4,0)),"") -> 5293 | V22: =IF($N22<>"",INDEX(Data!$B$9:$J$60,MATCH($N22,Data!$A$9:$A$60,0),MATCH(V$8,Data!$B$4:$J$4,0)),"") -> 156 | W22: =IF($N22<>"",INDEX(Data!$B$9:$J$60,MATCH($N22,Data!$A$9:$A$60,0),MATCH(W$8,Data!$B$4:$J$4,0)),"") -> 4514 | X22: =IF($N22<>"",(O22-R22)/R22,"") -> 0.16703704 | Y22: =IF($N22<>"",(P22-S22)/S22,"") -> 0.26315789 | Z22: =IF($N22<>"",(Q22-T22)/T22,"") -> 0.13647461 | AA22: =IF($N22<>"",(O22-U22)/U22,"") -> 0.19062913 | AB22: =IF($N22<>"",(P22-V22)/V22,"") -> 0.53846154 | AC22: =IF($N22<>"",(Q22-W22)/W22,"") -> 0.031236154 | AF22: =N22 -> Mosquit | AG22: =IF(AF22="","",INDEX(AA22:AC22,$D$6)+(ROW()/10000000000)+N("the row function is used here to make sure we have unique values to sort")) -> 0.19062914 | AP22: Aug | AQ22: =INDEX(Data!$K$9:$AT$60,MATCH(Calculation!$AP$11,Data!$A$9:$A$60,0),MATCH(Calculation!AQ$13&Calculation!$AP22&Calculation!AQ$14,INDEX(Data!$K$5:$AT$5&Data!$K$6:$AT$6&Data!$K$7:$AT$7,),0)) -> 0 | AR22: =INDEX(Data!$K$9:$AT$60,MATCH(Calculation!$AP$11,Data!$A$9:$A$60,0),MATCH(Calculation!AR$13&Calculation!$AP22&Calculation!AR$14,INDEX(Data!$K$5:$AT$5&Data!$K$6:$AT$6&Data!$K$7:$AT$7,),0)) -> 9323.8 | AS22: =INDEX(Data!$K$9:$AT$60,MATCH(Calculation!$AP$11,Data!$A$9:$A$60,0),MATCH(Calculation!AS$13&Calculation!$AP22&Calculation!AS$14,INDEX(Data!$K$5:$AT$5&Data!$K$6:$AT$6&Data!$K$7:$AT$7,),0)) -> 9732.8 | AV22: =LEFT(AP22,1) -> A | AW22: =IF(MATCH(cur_month,$AP$15:$AP$26,0)>=ROWS($AP$15:AP22),AQ22,NA()) -> #N/A | AX22: =IF($D$9,AR22,NA()) -> 9323.8 | AY22: =IF($D$10,AS22,NA()) -> 9732.8 | AZ22: =IF(AP22=cur_month,AW22,NA()) -> #N/A
B23: Sep | G23: Mirrrr | H23: Jellyfish | I23: Atmos | M23: =IF(N23<>"",ROW(A9),"") -> 9 | N23: =IF(INDEX(G23:I23,$D$4)="","",INDEX(G23:I23,$D$4)) -> Atmos | O23: =IF($N23<>"",INDEX(Data!$B$9:$J$60,MATCH($N23,Data!$A$9:$A$60,0),MATCH(O$8,Data!$B$4:$J$4,0)),"") -> 10675 | P23: =IF($N23<>"",INDEX(Data!$B$9:$J$60,MATCH($N23,Data!$A$9:$A$60,0),MATCH(P$8,Data!$B$4:$J$4,0)),"") -> 128 | Q23: =IF($N23<>"",INDEX(Data!$B$9:$J$60,MATCH($N23,Data!$A$9:$A$60,0),MATCH(Q$8,Data!$B$4:$J$4,0)),"") -> 8210 | R23: =IF($N23<>"",INDEX(Data!$B$9:$J$60,MATCH($N23,Data!$A$9:$A$60,0),MATCH(R$8,Data!$B$4:$J$4,0)),"") -> 10133 | S23: =IF($N23<>"",INDEX(Data!$B$9:$J$60,MATCH($N23,Data!$A$9:$A$60,0),MATCH(S$8,Data!$B$4:$J$4,0)),"") -> 89 | T23: =IF($N23<>"",INDEX(Data!$B$9:$J$60,MATCH($N23,Data!$A$9:$A$60,0),MATCH(T$8,Data!$B$4:$J$4,0)),"") -> 8179 | U23: =IF($N23<>"",INDEX(Data!$B$9:$J$60,MATCH($N23,Data!$A$9:$A$60,0),MATCH(U$8,Data!$B$4:$J$4,0)),"") -> 11178 | V23: =IF($N23<>"",INDEX(Data!$B$9:$J$60,MATCH($N23,Data!$A$9:$A$60,0),MATCH(V$8,Data!$B$4:$J$4,0)),"") -> 190 | W23: =IF($N23<>"",INDEX(Data!$B$9:$J$60,MATCH($N23,Data!$A$9:$A$60,0),MATCH(W$8,Data!$B$4:$J$4,0)),"") -> 8010 | X23: =IF($N23<>"",(O23-R23)/R23,"") -> 0.053488602 | Y23: =IF($N23<>"",(P23-S23)/S23,"") -> 0.43820225 | Z23: =IF($N23<>"",(Q23-T23)/T23,"") -> 0.0037901944 | AA23: =IF($N23<>"",(O23-U23)/U23,"") -> -0.044999105 | AB23: =IF($N23<>"",(P23-V23)/V23,"") -> -0.32631579 | AC23: =IF($N23<>"",(Q23-W23)/W23,"") -> 0.024968789 | AF23: =N23 -> Atmos | AG23: =IF(AF23="","",INDEX(AA23:AC23,$D$6)+(ROW()/10000000000)+N("the row function is used here to make sure we have unique values to sort")) -> -0.044999103 | AP23: Sep | AQ23: =INDEX(Data!$K$9:$AT$60,MATCH(Calculation!$AP$11,Data!$A$9:$A$60,0),MATCH(Calculation!AQ$13&Calculation!$AP23&Calculation!AQ$14,INDEX(Data!$K$5:$AT$5&Data!$K$6:$AT$6&Data!$K$7:$AT$7,),0)) -> 0 | AR23: =INDEX(Data!$K$9:$AT$60,MATCH(Calculation!$AP$11,Data!$A$9:$A$60,0),MATCH(Calculation!AR$13&Calculation!$AP23&Calculation!AR$14,INDEX(Data!$K$5:$AT$5&Data!$K$6:$AT$6&Data!$K$7:$AT$7,),0)) -> 10122.5 | AS23: =INDEX(Data!$K$9:$AT$60,MATCH(Calculation!$AP$11,Data!$A$9:$A$60,0),MATCH(Calculation!AS$13&Calculation!$AP23&Calculation!AS$14,INDEX(Data!$K$5:$AT$5&Data!$K$6:$AT$6&Data!$K$7:$AT$7,),0)) -> 11196.7 | AV23: =LEFT(AP23,1) -> S | AW23: =IF(MATCH(cur_month,$AP$15:$AP$26,0)>=ROWS($AP$15:AP23),AQ23,NA()) -> #N/A | AX23: =IF($D$9,AR23,NA()) -> 10122.5 | AY23: =IF($D$10,AS23,NA()) -> 11196.7 | AZ23: =IF(AP23=cur_month,AW23,NA()) -> #N/A
B24: Oct | G24: Halotot | H24: Aviatrr | I24: Scrap | M24: =IF(N24<>"",ROW(A10),"") -> 10 | N24: =IF(INDEX(G24:I24,$D$4)="","",INDEX(G24:I24,$D$4)) -> Scrap | O24: =IF($N24<>"",INDEX(Data!$B$9:$J$60,MATCH($N24,Data!$A$9:$A$60,0),MATCH(O$8,Data!$B$4:$J$4,0)),"") -> 13307 | P24: =IF($N24<>"",INDEX(Data!$B$9:$J$60,MATCH($N24,Data!$A$9:$A$60,0),MATCH(P$8,Data!$B$4:$J$4,0)),"") -> 862 | Q24: =IF($N24<>"",INDEX(Data!$B$9:$J$60,MATCH($N24,Data!$A$9:$A$60,0),MATCH(Q$8,Data!$B$4:$J$4,0)),"") -> 5279 | R24: =IF($N24<>"",INDEX(Data!$B$9:$J$60,MATCH($N24,Data!$A$9:$A$60,0),MATCH(R$8,Data!$B$4:$J$4,0)),"") -> 12127 | S24: =IF($N24<>"",INDEX(Data!$B$9:$J$60,MATCH($N24,Data!$A$9:$A$60,0),MATCH(S$8,Data!$B$4:$J$4,0)),"") -> 742 | T24: =IF($N24<>"",INDEX(Data!$B$9:$J$60,MATCH($N24,Data!$A$9:$A$60,0),MATCH(T$8,Data!$B$4:$J$4,0)),"") -> 5491 | U24: =IF($N24<>"",INDEX(Data!$B$9:$J$60,MATCH($N24,Data!$A$9:$A$60,0),MATCH(U$8,Data!$B$4:$J$4,0)),"") -> 13448 | V24: =IF($N24<>"",INDEX(Data!$B$9:$J$60,MATCH($N24,Data!$A$9:$A$60,0),MATCH(V$8,Data!$B$4:$J$4,0)),"") -> 905 | W24: =IF($N24<>"",INDEX(Data!$B$9:$J$60,MATCH($N24,Data!$A$9:$A$60,0),MATCH(W$8,Data!$B$4:$J$4,0)),"") -> 6062 | X24: =IF($N24<>"",(O24-R24)/R24,"") -> 0.097303538 | Y24: =IF($N24<>"",(P24-S24)/S24,"") -> 0.16172507 | Z24: =IF($N24<>"",(Q24-T24)/T24,"") -> -0.038608632 | AA24: =IF($N24<>"",(O24-U24)/U24,"") -> -0.01048483 | AB24: =IF($N24<>"",(P24-V24)/V24,"") -> -0.047513812 | AC24: =IF($N24<>"",(Q24-W24)/W24,"") -> -0.12916529 | AF24: =N24 -> Scrap | AG24: =IF(AF24="","",INDEX(AA24:AC24,$D$6)+(ROW()/10000000000)+N("the row function is used here to make sure we have unique values to sort")) -> -0.010484828 | AP24: Oct | AQ24: =INDEX(Data!$K$9:$AT$60,MATCH(Calculation!$AP$11,Data!$A$9:$A$60,0),MATCH(Calculation!AQ$13&Calculation!$AP24&Calculation!AQ$14,INDEX(Data!$K$5:$AT$5&Data!$K$6:$AT$6&Data!$K$7:$AT$7,),0)) -> 0 | AR24: =INDEX(Data!$K$9:$AT$60,MATCH(Calculation!$AP$11,Data!$A$9:$A$60,0),MATCH(Calculation!AR$13&Calculation!$AP24&Calculation!AR$14,INDEX(Data!$K$5:$AT$5&Data!$K$6:$AT$6&Data!$K$7:$AT$7,),0)) -> 10897.7 | AS24: =INDEX(Data!$K$9:$AT$60,MATCH(Calculation!$AP$11,Data!$A$9:$A$60,0),MATCH(Calculation!AS$13&Calculation!$AP24&Calculation!AS$14,INDEX(Data!$K$5:$AT$5&Data!$K$6:$AT$6&Data!$K$7:$AT$7,),0)) -> 12313.3 | AV24: =LEFT(AP24,1) -> O | AW24: =IF(MATCH(cur_month,$AP$15:$AP$26,0)>=ROWS($AP$15:AP24),AQ24,NA()) -> #N/A | AX24: =IF($D$9,AR24,NA()) -> 10897.7 | AY24: =IF($D$10,AS24,NA()) -> 12313.3 | AZ24: =IF(AP24=cur_month,AW24,NA()) -> #N/A
B25: Nov | G25: Flowrrr | H25: deRamblr | I25: Motocyco | M25: =IF(N25<>"",ROW(A11),"") -> 11 | N25: =IF(INDEX(G25:I25,$D$4)="","",INDEX(G25:I25,$D$4)) -> Motocyco | O25: =IF($N25<>"",INDEX(Data!$B$9:$J$60,MATCH($N25,Data!$A$9:$A$60,0),MATCH(O$8,Data!$B$4:$J$4,0)),"") -> 11182 | P25: =IF($N25<>"",INDEX(Data!$B$9:$J$60,MATCH($N25,Data!$A$9:$A$60,0),MATCH(P$8,Data!$B$4:$J$4,0)),"") -> 1193 | Q25: =IF($N25<>"",INDEX(Data!$B$9:$J$60,MATCH($N25,Data!$A$9:$A$60,0),MATCH(Q$8,Data!$B$4:$J$4,0)),"") -> 4311 | R25: =IF($N25<>"",INDEX(Data!$B$9:$J$60,MATCH($N25,Data!$A$9:$A$60,0),MATCH(R$8,Data!$B$4:$J$4,0)),"") -> 10457 | S25: =IF($N25<>"",INDEX(Data!$B$9:$J$60,MATCH($N25,Data!$A$9:$A$60,0),MATCH(S$8,Data!$B$4:$J$4,0)),"") -> 890 | T25: =IF($N25<>"",INDEX(Data!$B$9:$J$60,MATCH($N25,Data!$A$9:$A$60,0),MATCH(T$8,Data!$B$4:$J$4,0)),"") -> 4595 | U25: =IF($N25<>"",INDEX(Data!$B$9:$J$60,MATCH($N25,Data!$A$9:$A$60,0),MATCH(U$8,Data!$B$4:$J$4,0)),"") -> 9952 | V25: =IF($N25<>"",INDEX(Data!$B$9:$J$60,MATCH($N25,Data!$A$9:$A$60,0),MATCH(V$8,Data!$B$4:$J$4,0)),"") -> 810 | W25: =IF($N25<>"",INDEX(Data!$B$9:$J$60,MATCH($N25,Data!$A$9:$A$60,0),MATCH(W$8,Data!$B$4:$J$4,0)),"") -> 4298 | X25: =IF($N25<>"",(O25-R25)/R25,"") -> 0.069331548 | Y25: =IF($N25<>"",(P25-S25)/S25,"") -> 0.34044944 | Z25: =IF($N25<>"",(Q25-T25)/T25,"") -> -0.061806311 | AA25: =IF($N25<>"",(O25-U25)/U25,"") -> 0.12359325 | AB25: =IF($N25<>"",(P25-V25)/V25,"") -> 0.47283951 | AC25: =IF($N25<>"",(Q25-W25)/W25,"") -> 0.0030246626 | AF25: =N25 -> Motocyco | AG25: =IF(AF25="","",INDEX(AA25:AC25,$D$6)+(ROW()/10000000000)+N("the row function is used here to make sure we have unique values to sort")) -> 0.12359325 | AP25: Nov | AQ25: =INDEX(Data!$K$9:$AT$60,MATCH(Calculation!$AP$11,Data!$A$9:$A$60,0),MATCH(Calculation!AQ$13&Calculation!$AP25&Calculation!AQ$14,INDEX(Data!$K$5:$AT$5&Data!$K$6:$AT$6&Data!$K$7:$AT$7,),0)) -> 0 | AR25: =INDEX(Data!$K$9:$AT$60,MATCH(Calculation!$AP$11,Data!$A$9:$A$60,0),MATCH(Calculation!AR$13&Calculation!$AP25&Calculation!AR$14,INDEX(Data!$K$5:$AT$5&Data!$K$6:$AT$6&Data!$K$7:$AT$7,),0)) -> 11759 | AS25: =INDEX(Data!$K$9:$AT$60,MATCH(Calculation!$AP$11,Data!$A$9:$A$60,0),MATCH(Calculation!AS$13&Calculation!$AP25&Calculation!AS$14,INDEX(Data!$K$5:$AT$5&Data!$K$6:$AT$6&Data!$K$7:$AT$7,),0)) -> 13505.4 | AV25: =LEFT(AP25,1) -> N | AW25: =IF(MATCH(cur_month,$AP$15:$AP$26,0)>=ROWS($AP$15:AP25),AQ25,NA()) -> #N/A | AX25: =IF($D$9,AR25,NA()) -> 11759 | AY25: =IF($D$10,AS25,NA()) -> 13505.4 | AZ25: =IF(AP25=cur_month,AW25,NA()) -> #N/A
B26: Dec | G26: Silvrr | H26: Arcade | I26: Amplefio | M26: =IF(N26<>"",ROW(A12),"") -> 12 | N26: =IF(INDEX(G26:I26,$D$4)="","",INDEX(G26:I26,$D$4)) -> Amplefio | O26: =IF($N26<>"",INDEX(Data!$B$9:$J$60,MATCH($N26,Data!$A$9:$A$60,0),MATCH(O$8,Data!$B$4:$J$4,0)),"") -> 8250 | P26: =IF($N26<>"",INDEX(Data!$B$9:$J$60,MATCH($N26,Data!$A$9:$A$60,0),MATCH(P$8,Data!$B$4:$J$4,0)),"") -> 541 | Q26: =IF($N26<>"",INDEX(Data!$B$9:$J$60,MATCH($N26,Data!$A$9:$A$60,0),MATCH(Q$8,Data!$B$4:$J$4,0)),"") -> 5923 | R26: =IF($N26<>"",INDEX(Data!$B$9:$J$60,MATCH($N26,Data!$A$9:$A$60,0),MATCH(R$8,Data!$B$4:$J$4,0)),"") -> 8507 | S26: =IF($N26<>"",INDEX(Data!$B$9:$J$60,MATCH($N26,Data!$A$9:$A$60,0),MATCH(S$8,Data!$B$4:$J$4,0)),"") -> 369 | T26: =IF($N26<>"",INDEX(Data!$B$9:$J$60,MATCH($N26,Data!$A$9:$A$60,0),MATCH(T$8,Data!$B$4:$J$4,0)),"") -> 6622 | U26: =IF($N26<>"",INDEX(Data!$B$9:$J$60,MATCH($N26,Data!$A$9:$A$60,0),MATCH(U$8,Data!$B$4:$J$4,0)),"") -> 8899 | V26: =IF($N26<>"",INDEX(Data!$B$9:$J$60,MATCH($N26,Data!$A$9:$A$60,0),MATCH(V$8,Data!$B$4:$J$4,0)),"") -> 474 | W26: =IF($N26<>"",INDEX(Data!$B$9:$J$60,MATCH($N26,Data!$A$9:$A$60,0),MATCH(W$8,Data!$B$4:$J$4,0)),"") -> 6231 | X26: =IF($N26<>"",(O26-R26)/R26,"") -> -0.030210415 | Y26: =IF($N26<>"",(P26-S26)/S26,"") -> 0.46612466 | Z26: =IF($N26<>"",(Q26-T26)/T26,"") -> -0.10555723 | AA26: =IF($N26<>"",(O26-U26)/U26,"") -> -0.072929543 | AB26: =IF($N26<>"",(P26-V26)/V26,"") -> 0.14135021 | AC26: =IF($N26<>"",(Q26-W26)/W26,"") -> -0.049430268 | AF26: =N26 -> Amplefio | AG26: =IF(AF26="","",INDEX(AA26:AC26,$D$6)+(ROW()/10000000000)+N("the row function is used here to make sure we have unique values to sort")) -> -0.07292954 | AP26: Dec | AQ26: =INDEX(Data!$K$9:$AT$60,MATCH(Calculation!$AP$11,Data!$A$9:$A$60,0),MATCH(Calculation!AQ$13&Calculation!$AP26&Calculation!AQ$14,INDEX(Data!$K$5:$AT$5&Data!$K$6:$AT$6&Data!$K$7:$AT$7,),0)) -> 0 | AR26: =INDEX(Data!$K$9:$AT$60,MATCH(Calculation!$AP$11,Data!$A$9:$A$60,0),MATCH(Calculation!AR$13&Calculation!$AP26&Calculation!AR$14,INDEX(Data!$K$5:$AT$5&Data!$K$6:$AT$6&Data!$K$7:$AT$7,),0)) -> 11946 | AS26: =INDEX(Data!$K$9:$AT$60,MATCH(Calculation!$AP$11,Data!$A$9:$A$60,0),MATCH(Calculation!AS$13&Calculation!$AP26&Calculation!AS$14,INDEX(Data!$K$5:$AT$5&Data!$K$6:$AT$6&Data!$K$7:$AT$7,),0)) -> 13380.7 | AV26: =LEFT(AP26,1) -> D | AW26: =IF(MATCH(cur_month,$AP$15:$AP$26,0)>=ROWS($AP$15:AP26),AQ26,NA()) -> #N/A | AX26: =IF($D$9,AR26,NA()) -> 11946 | AY26: =IF($D$10,AS26,NA()) -> 13380.7 | AZ26: =IF(AP26=cur_month,AW26,NA()) -> #N/A
G27: Dasring | I27: Strex | M27: =IF(N27<>"",ROW(A13),"") -> 13 | N27: =IF(INDEX(G27:I27,$D$4)="","",INDEX(G27:I27,$D$4)) -> Strex | O27: =IF($N27<>"",INDEX(Data!$B$9:$J$60,MATCH($N27,Data!$A$9:$A$60,0),MATCH(O$8,Data!$B$4:$J$4,0)),"") -> 8152 | P27: =IF($N27<>"",INDEX(Data!$B$9:$J$60,MATCH($N27,Data!$A$9:$A$60,0),MATCH(P$8,Data!$B$4:$J$4,0)),"") -> 258 | Q27: =IF($N27<>"",INDEX(Data!$B$9:$J$60,MATCH($N27,Data!$A$9:$A$60,0),MATCH(Q$8,Data!$B$4:$J$4,0)),"") -> 5700 | R27: =IF($N27<>"",INDEX(Data!$B$9:$J$60,MATCH($N27,Data!$A$9:$A$60,0),MATCH(R$8,Data!$B$4:$J$4,0)),"") -> 10832 | S27: =IF($N27<>"",INDEX(Data!$B$9:$J$60,MATCH($N27,Data!$A$9:$A$60,0),MATCH(S$8,Data!$B$4:$J$4,0)),"") -> 577 | T27: =IF($N27<>"",INDEX(Data!$B$9:$J$60,MATCH($N27,Data!$A$9:$A$60,0),MATCH(T$8,Data!$B$4:$J$4,0)),"") -> 5100 | U27: =IF($N27<>"",INDEX(Data!$B$9:$J$60,MATCH($N27,Data!$A$9:$A$60,0),MATCH(U$8,Data!$B$4:$J$4,0)),"") -> 9698 | V27: =IF($N27<>"",INDEX(Data!$B$9:$J$60,MATCH($N27,Data!$A$9:$A$60,0),MATCH(V$8,Data!$B$4:$J$4,0)),"") -> 350 | W27: =IF($N27<>"",INDEX(Data!$B$9:$J$60,MATCH($N27,Data!$A$9:$A$60,0),MATCH(W$8,Data!$B$4:$J$4,0)),"") -> 5200 | X27: =IF($N27<>"",(O27-R27)/R27,"") -> -0.24741507 | Y27: =IF($N27<>"",(P27-S27)/S27,"") -> -0.55285962 | Z27: =IF($N27<>"",(Q27-T27)/T27,"") -> 0.11764706 | AA27: =IF($N27<>"",(O27-U27)/U27,"") -> -0.15941431 | AB27: =IF($N27<>"",(P27-V27)/V27,"") -> -0.26285714 | AC27: =IF($N27<>"",(Q27-W27)/W27,"") -> 0.096153846 | AF27: =N27 -> Strex | AG27: =IF(AF27="","",INDEX(AA27:AC27,$D$6)+(ROW()/10000000000)+N("the row function is used here to make sure we have unique values to sort")) -> -0.15941431
G28: Rehire | M28: =IF(N28<>"",ROW(A14),"") | N28: =IF(INDEX(G28:I28,$D$4)="","",INDEX(G28:I28,$D$4)) | O28: =IF($N28<>"",INDEX(Data!$B$9:$J$60,MATCH($N28,Data!$A$9:$A$60,0),MATCH(O$8,Data!$B$4:$J$4,0)),"") | P28: =IF($N28<>"",INDEX(Data!$B$9:$J$60,MATCH($N28,Data!$A$9:$A$60,0),MATCH(P$8,Data!$B$4:$J$4,0)),"") | Q28: =IF($N28<>"",INDEX(Data!$B$9:$J$60,MATCH($N28,Data!$A$9:$A$60,0),MATCH(Q$8,Data!$B$4:$J$4,0)),"") | R28: =IF($N28<>"",INDEX(Data!$B$9:$J$60,MATCH($N28,Data!$A$9:$A$60,0),MATCH(R$8,Data!$B$4:$J$4,0)),"") | S28: =IF($N28<>"",INDEX(Data!$B$9:$J$60,MATCH($N28,Data!$A$9:$A$60,0),MATCH(S$8,Data!$B$4:$J$4,0)),"") | T28: =IF($N28<>"",INDEX(Data!$B$9:$J$60,MATCH($N28,Data!$A$9:$A$60,0),MATCH(T$8,Data!$B$4:$J$4,0)),"") | U28: =IF($N28<>"",INDEX(Data!$B$9:$J$60,MATCH($N28,Data!$A$9:$A$60,0),MATCH(U$8,Data!$B$4:$J$4,0)),"") | V28: =IF($N28<>"",INDEX(Data!$B$9:$J$60,MATCH($N28,Data!$A$9:$A$60,0),MATCH(V$8,Data!$B$4:$J$4,0)),"") | W28: =IF($N28<>"",INDEX(Data!$B$9:$J$60,MATCH($N28,Data!$A$9:$A$60,0),MATCH(W$8,Data!$B$4:$J$4,0)),"") | X28: =IF($N28<>"",(O28-R28)/R28,"") | Y28: =IF($N28<>"",(P28-S28)/S28,"") | Z28: =IF($N28<>"",(Q28-T28)/T28,"") | AA28: =IF($N28<>"",(O28-U28)/U28,"") | AB28: =IF($N28<>"",(P28-V28)/V28,"") | AC28: =IF($N28<>"",(Q28-W28)/W28,"") | AF28: =N28 | AG28: =IF(AF28="","",INDEX(AA28:AC28,$D$6)+(ROW()/10000000000)+N("the row function is used here to make sure we have unique values to sort"))
G29: Didactic | M29: =IF(N29<>"",ROW(A15),"") | N29: =IF(INDEX(G29:I29,$D$4)="","",INDEX(G29:I29,$D$4)) | O29: =IF($N29<>"",INDEX(Data!$B$9:$J$60,MATCH($N29,Data!$A$9:$A$60,0),MATCH(O$8,Data!$B$4:$J$4,0)),"") | P29: =IF($N29<>"",INDEX(Data!$B$9:$J$60,MATCH($N29,Data!$A$9:$A$60,0),MATCH(P$8,Data!$B$4:$J$4,0)),"") | Q29: =IF($N29<>"",INDEX(Data!$B$9:$J$60,MATCH($N29,Data!$A$9:$A$60,0),MATCH(Q$8,Data!$B$4:$J$4,0)),"") | R29: =IF($N29<>"",INDEX(Data!$B$9:$J$60,MATCH($N29,Data!$A$9:$A$60,0),MATCH(R$8,Data!$B$4:$J$4,0)),"") | S29: =IF($N29<>"",INDEX(Data!$B$9:$J$60,MATCH($N29,Data!$A$9:$A$60,0),MATCH(S$8,Data!$B$4:$J$4,0)),"") | T29: =IF($N29<>"",INDEX(Data!$B$9:$J$60,MATCH($N29,Data!$A$9:$A$60,0),MATCH(T$8,Data!$B$4:$J$4,0)),"") | U29: =IF($N29<>"",INDEX(Data!$B$9:$J$60,MATCH($N29,Data!$A$9:$A$60,0),MATCH(U$8,Data!$B$4:$J$4,0)),"") | V29: =IF($N29<>"",INDEX(Data!$B$9:$J$60,MATCH($N29,Data!$A$9:$A$60,0),MATCH(V$8,Data!$B$4:$J$4,0)),"") | W29: =IF($N29<>"",INDEX(Data!$B$9:$J$60,MATCH($N29,Data!$A$9:$A$60,0),MATCH(W$8,Data!$B$4:$J$4,0)),"") | X29: =IF($N29<>"",(O29-R29)/R29,"") | Y29: =IF($N29<>"",(P29-S29)/S29,"") | Z29: =IF($N29<>"",(Q29-T29)/T29,"") | AA29: =IF($N29<>"",(O29-U29)/U29,"") | AB29: =IF($N29<>"",(P29-V29)/V29,"") | AC29: =IF($N29<>"",(Q29-W29)/W29,"") | AF29: =N29 | AG29: =IF(AF29="","",INDEX(AA29:AC29,$D$6)+(ROW()/10000000000)+N("the row function is used here to make sure we have unique values to sort"))
M30: =IF(N30<>"",ROW(A16),"") | N30: =IF(INDEX(G30:I30,$D$4)="","",INDEX(G30:I30,$D$4)) | O30: =IF($N30<>"",INDEX(Data!$B$9:$J$60,MATCH($N30,Data!$A$9:$A$60,0),MATCH(O$8,Data!$B$4:$J$4,0)),"") | P30: =IF($N30<>"",INDEX(Data!$B$9:$J$60,MATCH($N30,Data!$A$9:$A$60,0),MATCH(P$8,Data!$B$4:$J$4,0)),"") | Q30: =IF($N30<>"",INDEX(Data!$B$9:$J$60,MATCH($N30,Data!$A$9:$A$60,0),MATCH(Q$8,Data!$B$4:$J$4,0)),"") | R30: =IF($N30<>"",INDEX(Data!$B$9:$J$60,MATCH($N30,Data!$A$9:$A$60,0),MATCH(R$8,Data!$B$4:$J$4,0)),"") | S30: =IF($N30<>"",INDEX(Data!$B$9:$J$60,MATCH($N30,Data!$A$9:$A$60,0),MATCH(S$8,Data!$B$4:$J$4,0)),"") | T30: =IF($N30<>"",INDEX(Data!$B$9:$J$60,MATCH($N30,Data!$A$9:$A$60,0),MATCH(T$8,Data!$B$4:$J$4,0)),"") | U30: =IF($N30<>"",INDEX(Data!$B$9:$J$60,MATCH($N30,Data!$A$9:$A$60,0),MATCH(U$8,Data!$B$4:$J$4,0)),"") | V30: =IF($N30<>"",INDEX(Data!$B$9:$J$60,MATCH($N30,Data!$A$9:$A$60,0),MATCH(V$8,Data!$B$4:$J$4,0)),"") | W30: =IF($N30<>"",INDEX(Data!$B$9:$J$60,MATCH($N30,Data!$A$9:$A$60,0),MATCH(W$8,Data!$B$4:$J$4,0)),"") | X30: =IF($N30<>"",(O30-R30)/R30,"") | Y30: =IF($N30<>"",(P30-S30)/S30,"") | Z30: =IF($N30<>"",(Q30-T30)/T30,"") | AA30: =IF($N30<>"",(O30-U30)/U30,"") | AB30: =IF($N30<>"",(P30-V30)/V30,"") | AC30: =IF($N30<>"",(Q30-W30)/W30,"") | AF30: =N30 | AG30: =IF(AF30="","",INDEX(AA30:AC30,$D$6)+(ROW()/10000000000)+N("the row function is used here to make sure we have unique values to sort"))
M31: =IF(N31<>"",ROW(A17),"") | N31: =IF(INDEX(G31:I31,$D$4)="","",INDEX(G31:I31,$D$4)) | O31: =IF($N31<>"",INDEX(Data!$B$9:$J$60,MATCH($N31,Data!$A$9:$A$60,0),MATCH(O$8,Data!$B$4:$J$4,0)),"") | P31: =IF($N31<>"",INDEX(Data!$B$9:$J$60,MATCH($N31,Data!$A$9:$A$60,0),MATCH(P$8,Data!$B$4:$J$4,0)),"") | Q31: =IF($N31<>"",INDEX(Data!$B$9:$J$60,MATCH($N31,Data!$A$9:$A$60,0),MATCH(Q$8,Data!$B$4:$J$4,0)),"") | R31: =IF($N31<>"",INDEX(Data!$B$9:$J$60,MATCH($N31,Data!$A$9:$A$60,0),MATCH(R$8,Data!$B$4:$J$4,0)),"") | S31: =IF($N31<>"",INDEX(Data!$B$9:$J$60,MATCH($N31,Data!$A$9:$A$60,0),MATCH(S$8,Data!$B$4:$J$4,0)),"") | T31: =IF($N31<>"",INDEX(Data!$B$9:$J$60,MATCH($N31,Data!$A$9:$A$60,0),MATCH(T$8,Data!$B$4:$J$4,0)),"") | U31: =IF($N31<>"",INDEX(Data!$B$9:$J$60,MATCH($N31,Data!$A$9:$A$60,0),MATCH(U$8,Data!$B$4:$J$4,0)),"") | V31: =IF($N31<>"",INDEX(Data!$B$9:$J$60,MATCH($N31,Data!$A$9:$A$60,0),MATCH(V$8,Data!$B$4:$J$4,0)),"") | W31: =IF($N31<>"",INDEX(Data!$B$9:$J$60,MATCH($N31,Data!$A$9:$A$60,0),MATCH(W$8,Data!$B$4:$J$4,0)),"") | X31: =IF($N31<>"",(O31-R31)/R31,"") | Y31: =IF($N31<>"",(P31-S31)/S31,"") | Z31: =IF($N31<>"",(Q31-T31)/T31,"") | AA31: =IF($N31<>"",(O31-U31)/U31,"") | AB31: =IF($N31<>"",(P31-V31)/V31,"") | AC31: =IF($N31<>"",(Q31-W31)/W31,"") | AF31: =N31 | AG31: =IF(AF31="","",INDEX(AA31:AC31,$D$6)+(ROW()/10000000000)+N("the row function is used here to make sure we have unique values to sort"))
M32: =IF(N32<>"",ROW(A18),"") | N32: =IF(INDEX(G32:I32,$D$4)="","",INDEX(G32:I32,$D$4)) | O32: =IF($N32<>"",INDEX(Data!$B$9:$J$60,MATCH($N32,Data!$A$9:$A$60,0),MATCH(O$8,Data!$B$4:$J$4,0)),"") | P32: =IF($N32<>"",INDEX(Data!$B$9:$J$60,MATCH($N32,Data!$A$9:$A$60,0),MATCH(P$8,Data!$B$4:$J$4,0)),"") | Q32: =IF($N32<>"",INDEX(Data!$B$9:$J$60,MATCH($N32,Data!$A$9:$A$60,0),MATCH(Q$8,Data!$B$4:$J$4,0)),"") | R32: =IF($N32<>"",INDEX(Data!$B$9:$J$60,MATCH($N32,Data!$A$9:$A$60,0),MATCH(R$8,Data!$B$4:$J$4,0)),"") | S32: =IF($N32<>"",INDEX(Data!$B$9:$J$60,MATCH($N32,Data!$A$9:$A$60,0),MATCH(S$8,Data!$B$4:$J$4,0)),"") | T32: =IF($N32<>"",INDEX(Data!$B$9:$J$60,MATCH($N32,Data!$A$9:$A$60,0),MATCH(T$8,Data!$B$4:$J$4,0)),"") | U32: =IF($N32<>"",INDEX(Data!$B$9:$J$60,MATCH($N32,Data!$A$9:$A$60,0),MATCH(U$8,Data!$B$4:$J$4,0)),"") | V32: =IF($N32<>"",INDEX(Data!$B$9:$J$60,MATCH($N32,Data!$A$9:$A$60,0),MATCH(V$8,Data!$B$4:$J$4,0)),"") | W32: =IF($N32<>"",INDEX(Data!$B$9:$J$60,MATCH($N32,Data!$A$9:$A$60,0),MATCH(W$8,Data!$B$4:$J$4,0)),"") | X32: =IF($N32<>"",(O32-R32)/R32,"") | Y32: =IF($N32<>"",(P32-S32)/S32,"") | Z32: =IF($N32<>"",(Q32-T32)/T32,"") | AA32: =IF($N32<>"",(O32-U32)/U32,"") | AB32: =IF($N32<>"",(P32-V32)/V32,"") | AC32: =IF($N32<>"",(Q32-W32)/W32,"") | AF32: =N32 | AG32: =IF(AF32="","",INDEX(AA32:AC32,$D$6)+(ROW()/10000000000)+N("the row function is used here to make sure we have unique values to sort"))
M33: =IF(N33<>"",ROW(A19),"") | N33: =IF(INDEX(G33:I33,$D$4)="","",INDEX(G33:I33,$D$4)) | O33: =IF($N33<>"",INDEX(Data!$B$9:$J$60,MATCH($N33,Data!$A$9:$A$60,0),MATCH(O$8,Data!$B$4:$J$4,0)),"") | P33: =IF($N33<>"",INDEX(Data!$B$9:$J$60,MATCH($N33,Data!$A$9:$A$60,0),MATCH(P$8,Data!$B$4:$J$4,0)),"") | Q33: =IF($N33<>"",INDEX(Data!$B$9:$J$60,MATCH($N33,Data!$A$9:$A$60,0),MATCH(Q$8,Data!$B$4:$J$4,0)),"") | R33: =IF($N33<>"",INDEX(Data!$B$9:$J$60,MATCH($N33,Data!$A$9:$A$60,0),MATCH(R$8,Data!$B$4:$J$4,0)),"") | S33: =IF($N33<>"",INDEX(Data!$B$9:$J$60,MATCH($N33,Data!$A$9:$A$60,0),MATCH(S$8,Data!$B$4:$J$4,0)),"") | T33: =IF($N33<>"",INDEX(Data!$B$9:$J$60,MATCH($N33,Data!$A$9:$A$60,0),MATCH(T$8,Data!$B$4:$J$4,0)),"") | U33: =IF($N33<>"",INDEX(Data!$B$9:$J$60,MATCH($N33,Data!$A$9:$A$60,0),MATCH(U$8,Data!$B$4:$J$4,0)),"") | V33: =IF($N33<>"",INDEX(Data!$B$9:$J$60,MATCH($N33,Data!$A$9:$A$60,0),MATCH(V$8,Data!$B$4:$J$4,0)),"") | W33: =IF($N33<>"",INDEX(Data!$B$9:$J$60,MATCH($N33,Data!$A$9:$A$60,0),MATCH(W$8,Data!$B$4:$J$4,0)),"") | X33: =IF($N33<>"",(O33-R33)/R33,"") | Y33: =IF($N33<>"",(P33-S33)/S33,"") | Z33: =IF($N33<>"",(Q33-T33)/T33,"") | AA33: =IF($N33<>"",(O33-U33)/U33,"") | AB33: =IF($N33<>"",(P33-V33)/V33,"") | AC33: =IF($N33<>"",(Q33-W33)/W33,"") | AF33: =N33 | AG33: =IF(AF33="","",INDEX(AA33:AC33,$D$6)+(ROW()/10000000000)+N("the row function is used here to make sure we have unique values to sort"))
M34: =IF(N34<>"",ROW(A20),"") | N34: =IF(INDEX(G34:I34,$D$4)="","",INDEX(G34:I34,$D$4)) | O34: =IF($N34<>"",INDEX(Data!$B$9:$J$60,MATCH($N34,Data!$A$9:$A$60,0),MATCH(O$8,Data!$B$4:$J$4,0)),"") | P34: =IF($N34<>"",INDEX(Data!$B$9:$J$60,MATCH($N34,Data!$A$9:$A$60,0),MATCH(P$8,Data!$B$4:$J$4,0)),"") | Q34: =IF($N34<>"",INDEX(Data!$B$9:$J$60,MATCH($N34,Data!$A$9:$A$60,0),MATCH(Q$8,Data!$B$4:$J$4,0)),"") | R34: =IF($N34<>"",INDEX(Data!$B$9:$J$60,MATCH($N34,Data!$A$9:$A$60,0),MATCH(R$8,Data!$B$4:$J$4,0)),"") | S34: =IF($N34<>"",INDEX(Data!$B$9:$J$60,MATCH($N34,Data!$A$9:$A$60,0),MATCH(S$8,Data!$B$4:$J$4,0)),"") | T34: =IF($N34<>"",INDEX(Data!$B$9:$J$60,MATCH($N34,Data!$A$9:$A$60,0),MATCH(T$8,Data!$B$4:$J$4,0)),"") | U34: =IF($N34<>"",INDEX(Data!$B$9:$J$60,MATCH($N34,Data!$A$9:$A$60,0),MATCH(U$8,Data!$B$4:$J$4,0)),"") | V34: =IF($N34<>"",INDEX(Data!$B$9:$J$60,MATCH($N34,Data!$A$9:$A$60,0),MATCH(V$8,Data!$B$4:$J$4,0)),"") | W34: =IF($N34<>"",INDEX(Data!$B$9:$J$60,MATCH($N34,Data!$A$9:$A$60,0),MATCH(W$8,Data!$B$4:$J$4,0)),"") | X34: =IF($N34<>"",(O34-R34)/R34,"") | Y34: =IF($N34<>"",(P34-S34)/S34,"") | Z34: =IF($N34<>"",(Q34-T34)/T34,"") | AA34: =IF($N34<>"",(O34-U34)/U34,"") | AB34: =IF($N34<>"",(P34-V34)/V34,"") | AC34: =IF($N34<>"",(Q34-W34)/W34,"") | AF34: =N34 | AG34: =IF(AF34="","",INDEX(AA34:AC34,$D$6)+(ROW()/10000000000)+N("the row function is used here to make sure we have unique values to sort"))
N36: =INDEX(G14:I14,D4) -> Utility Apps | O36: =IF($N36<>"",INDEX(Data!$B$9:$J$60,MATCH($N36,Data!$A$9:$A$60,0),MATCH(O$8,Data!$B$4:$J$4,0)),"") -> 189978.5 | P36: =IF($N36<>"",INDEX(Data!$B$9:$J$60,MATCH($N36,Data!$A$9:$A$60,0),MATCH(P$8,Data!$B$4:$J$4,0)),"") -> 8869.2 | Q36: =IF($N36<>"",INDEX(Data!$B$9:$J$60,MATCH($N36,Data!$A$9:$A$60,0),MATCH(Q$8,Data!$B$4:$J$4,0)),"") -> 91467.1 | R36: =IF($N36<>"",INDEX(Data!$B$9:$J$60,MATCH($N36,Data!$A$9:$A$60,0),MATCH(R$8,Data!$B$4:$J$4,0)),"") -> 187118.2 | S36: =IF($N36<>"",INDEX(Data!$B$9:$J$60,MATCH($N36,Data!$A$9:$A$60,0),MATCH(S$8,Data!$B$4:$J$4,0)),"") -> 7865.9 | T36: =IF($N36<>"",INDEX(Data!$B$9:$J$60,MATCH($N36,Data!$A$9:$A$60,0),MATCH(T$8,Data!$B$4:$J$4,0)),"") -> 97100.3 | U36: =IF($N36<>"",INDEX(Data!$B$9:$J$60,MATCH($N36,Data!$A$9:$A$60,0),MATCH(U$8,Data!$B$4:$J$4,0)),"") -> 181464.8 | V36: =IF($N36<>"",INDEX(Data!$B$9:$J$60,MATCH($N36,Data!$A$9:$A$60,0),MATCH(V$8,Data!$B$4:$J$4,0)),"") -> 8122.2 | W36: =IF($N36<>"",INDEX(Data!$B$9:$J$60,MATCH($N36,Data!$A$9:$A$60,0),MATCH(W$8,Data!$B$4:$J$4,0)),"") -> 94780.8 | X36: =IF($N36<>"",(O36-R36)/R36,"") -> 0.01528606 | Y36: =IF($N36<>"",(P36-S36)/S36,"") -> 0.12755057 | Z36: =IF($N36<>"",(Q36-T36)/T36,"") -> -0.058014239 | AA36: =IF($N36<>"",(R36-U36)/U36,"") -> 0.031154251 | AB36: =IF($N36<>"",(S36-V36)/V36,"") -> -0.03155549 | AC36: =IF($N36<>"",(T36-W36)/W36,"") -> 0.024472256
N38: Calculations for header | X38: Calculations for data bars in scrolling table
N39: Revenue A-B | O39: =O36-U36 -> 8513.7 | P39: =IF(O39>0,"Over Budget",IF(O39<0,"Under Budget")) -> Over Budget | X39: Min Rev % | Y39: =MIN(X15:X34) -> -0.24741507
N40: Profit A-B | O40: =P36-V36 -> 747 | P40: =IF(O40>0,"Over Budget",IF(O40<0,"Under Budget")) -> Over Budget | X40: Max Rev % | Y40: =MAX(X15:X34) -> 0.16703704
N41: Cash A-B | O41: =Q36-W36 -> -3313.7 | P41: =IF(O41>0,"Over Budget",IF(O41<0,"Under Budget")) -> Under Budget | X41: Min Profit % | Y41: =MIN(Y15:Y34) -> -0.55285962
X42: Max Profit % | Y42: =MAX(Y15:Y34) -> 0.46612466
X43: Min Cash % | Y43: =MIN(Z15:Z34) -> -0.18720539
X44: Max Cash % | Y44: =MAX(Z15:Z34) -> 0.13647461

Sheet Data
A1: Connected to Database via add-in
